Workbook
Name Z_89E132C0_7630_11D1_8600_87467182CD24_.wvu.Cols: Analysis!$AS:$AX
Name Z_89E132C0_7630_11D1_8600_87467182CD24_.wvu.Cols: volume!$AL:$AQ
Name Z_89E132C0_7630_11D1_8600_87467182CD24_.wvu.PrintArea: Analysis!$A$1:$AR$51
Name Z_89E132C0_7630_11D1_8600_87467182CD24_.wvu.PrintArea: volume!$A$1:$AK$51
Name Z_89E132C0_7630_11D1_8600_87467182CD24_.wvu.Rows: Report!$78:$78

Sheet Header
A1: Traffic Volume Counts
A3: ชื่อจุดสำรวจ | B3: หลักสี่
A4: หมายเลขสัญญาณไฟจราจร | B4: 500
A5: พิกัด (ละติจูด,ลองจิจูด) | B5: 13.884608 100.580908
A6: ถนนที่สำรวจ | B6: แจ้งวัฒนะ - กำแพงเพชร
A7: วัน-เดือน-ปี ที่สำรวจ | B7: 20 พฤษภาคม 2569
A8: สภาพอากาศ | B8: ปกติ
A9: ประเภททางแยก | B9: สี่แยก
A11: NB road_ชื่อถนน | B11: ถนนกำแพงเพชร 6
A12: EB road_ชื่อถนน | B12: ถนนแจ้งวัฒนะ
A13: SB road_ชื่อถนน | B13: ถนนกำแพงเพชร 6
A14: WB road_ชื่อถนน | B14: ถนนแจ้งวัฒนะ
A17: SELECTED OBJECT CLASSES | B17: รถยนต์/ ตู้,ปิคอัพ/ รถเมล์ใหญ่/ รถเมล์เล็ก/ รถบรรทุก/ รถสามล้อ
A18: PCU VALUES
A19: CAR | B19: 1
A20: VAN | B20: 1
A21: BUS | B21: 2.1
A22: TRUCK | B22: 1.5
A23: HEAVY TRUCK | B23: 2.5
A24: TRI-CYCLE | B24: 0.93

Sheet volume
A1: ทิศทาง | E1: NB1 | L1: NB2 | S1: NB3 | Z1: NB4 | AG1: EB5 | AN1: EB6 | AU1: EB7 | BB1: EB8 | BI1: SB9 | BP1: SB10 | BW1: SB11 | CD1: SB12 | CK1: WB13 | CR1: WB14 | CY1: WB15 | DF1: WB16 | DM1: NB*1 | DT1: NB2* | EA1: NB*3 | EO1: EB*5 | EV1: EB6* | FC1: EB*7 | FQ1: SB*9 | FX1: SB10* | GE1: SB*11 | GS1: WB*13 | GZ1: WB14* | HG1: WB*15
A2: เวลา | B2: รถยนต์ | C2: ตู้,ปิคอัพ | D2: เมล์ใหญ่ | E2: เมล์เล็ก | F2: บรรทุก | G2: สามล้อ | H2: SUM | I2: รถยนต์ | J2: ตู้,ปิคอัพ | K2: เมล์ใหญ่ | L2: เมล์เล็ก | M2: บรรทุก | N2: สามล้อ | O2: SUM | P2: รถยนต์ | Q2: ตู้,ปิคอัพ | R2: เมล์ใหญ่ | S2: เมล์เล็ก | T2: บรรทุก | U2: สามล้อ | V2: SUM | W2: รถยนต์ | X2: ตู้,ปิคอัพ | Y2: เมล์ใหญ่ | Z2: เมล์เล็ก | AA2: บรรทุก | AB2: สามล้อ | AC2: SUM | AD2: รถยนต์ | AE2: ตู้,ปิคอัพ | AF2: เมล์ใหญ่ | AG2: เมล์เล็ก | AH2: บรรทุก | AI2: สามล้อ | AJ2: SUM | AK2: รถยนต์ | AL2: ตู้,ปิคอัพ | AM2: เมล์ใหญ่ | AN2: เมล์เล็ก | AO2: บรรทุก | AP2: สามล้อ | AQ2: SUM | AR2: รถยนต์ | AS2: ตู้,ปิคอัพ | AT2: เมล์ใหญ่ | AU2: เมล์เล็ก | AV2: บรรทุก | AW2: สามล้อ | AX2: SUM | AY2: รถยนต์ | AZ2: ตู้,ปิคอัพ | BA2: เมล์ใหญ่ | BB2: เมล์เล็ก | BC2: บรรทุก | BD2: สามล้อ | BE2: SUM | BF2: รถยนต์ | BG2: ตู้,ปิคอัพ | BH2: เมล์ใหญ่ | BI2: เมล์เล็ก | BJ2: บรรทุก | BK2: สามล้อ | BL2: SUM | BM2: รถยนต์ | BN2: ตู้,ปิคอัพ | BO2: เมล์ใหญ่ | BP2: เมล์เล็ก | BQ2: บรรทุก | BR2: สามล้อ | BS2: SUM | BT2: รถยนต์ | BU2: ตู้,ปิคอัพ | BV2: เมล์ใหญ่ | BW2: เมล์เล็ก | BX2: บรรทุก | BY2: สามล้อ | BZ2: SUM | CA2: รถยนต์ | CB2: ตู้,ปิคอัพ | CC2: เมล์ใหญ่ | CD2: เมล์เล็ก | CE2: บรรทุก | CF2: สามล้อ | CG2: SUM | CH2: รถยนต์ | CI2: ตู้,ปิคอัพ | CJ2: เมล์ใหญ่ | CK2: เมล์เล็ก | CL2: บรรทุก | CM2: สามล้อ | CN2: SUM | CO2: รถยนต์ | CP2: ตู้,ปิคอัพ | CQ2: เมล์ใหญ่ | CR2: เมล์เล็ก | CS2: บรรทุก | CT2: สามล้อ | CU2: SUM | CV2: รถยนต์ | CW2: ตู้,ปิคอัพ | CX2: เมล์ใหญ่ | CY2: เมล์เล็ก | CZ2: บรรทุก | DA2: สามล้อ | DB2: SUM | DC2: รถยนต์ | DD2: ตู้,ปิคอัพ | DE2: เมล์ใหญ่ | DF2: เมล์เล็ก | DG2: บรรทุก | DH2: สามล้อ | DI2: SUM | DJ2: รถยนต์ | DK2: ตู้,ปิคอัพ | DL2: เมล์ใหญ่ | DM2: เมล์เล็ก | DN2: บรรทุก | DO2: สามล้อ | DP2: SUM | DQ2: รถยนต์ | DR2: ตู้,ปิคอัพ | DS2: เมล์ใหญ่ | DT2: เมล์เล็ก | DU2: บรรทุก | DV2: สามล้อ | DW2: SUM | DX2: รถยนต์ | DY2: ตู้,ปิคอัพ | DZ2: เมล์ใหญ่ | EA2: เมล์เล็ก | EB2: บรรทุก | EC2: สามล้อ | ED2: SUM | EL2: รถยนต์ | EM2: ตู้,ปิคอัพ | EN2: เมล์ใหญ่ | EO2: เมล์เล็ก | EP2: บรรทุก | EQ2: สามล้อ | ER2: SUM | ES2: รถยนต์ | ET2: ตู้,ปิคอัพ | EU2: เมล์ใหญ่ | EV2: เมล์เล็ก | EW2: บรรทุก | EX2: สามล้อ | EY2: SUM | EZ2: รถยนต์ | FA2: ตู้,ปิคอัพ | FB2: เมล์ใหญ่ | FC2: เมล์เล็ก | FD2: บรรทุก | FE2: สามล้อ | FF2: SUM | FN2: รถยนต์ | FO2: ตู้,ปิคอัพ | FP2: เมล์ใหญ่ | FQ2: เมล์เล็ก | FR2: บรรทุก | FS2: สามล้อ | FT2: SUM | FU2: รถยนต์ | FV2: ตู้,ปิคอัพ | FW2: เมล์ใหญ่ | FX2: เมล์เล็ก | FY2: บรรทุก | FZ2: สามล้อ | GA2: SUM | GB2: รถยนต์ | GC2: ตู้,ปิคอัพ | GD2: เมล์ใหญ่ | GE2: เมล์เล็ก | GF2: บรรทุก | GG2: สามล้อ | GH2: SUM | GP2: รถยนต์ | GQ2: ตู้,ปิคอัพ | GR2: เมล์ใหญ่ | GS2: เมล์เล็ก | GT2: บรรทุก | GU2: สามล้อ | GV2: SUM | GW2: รถยนต์ | GX2: ตู้,ปิคอัพ | GY2: เมล์ใหญ่ | GZ2: เมล์เล็ก | HA2: บรรทุก | HB2: สามล้อ | HC2: SUM | HD2: รถยนต์ | HE2: ตู้,ปิคอัพ | HF2: เมล์ใหญ่ | HG2: เมล์เล็ก | HH2: บรรทุก | HI2: สามล้อ | HJ2: SUM
A3: 7.00-7.15 | B3: 38 | C3: 7 | F3: 1 | H3: =SUM(B3:G3) -> 46 | I3: 22 | J3: 5 | O3: =SUM(I3:N3) -> 27 | P3: 29 | Q3: 9 | V3: =SUM(P3:U3) -> 38 | AC3: =SUM(W3:AB3) -> 0 | AD3: 48 | AE3: 18 | AH3: 1 | AJ3: =SUM(AD3:AI3) -> 67 | AK3: 191 | AL3: 39 | AQ3: =SUM(AK3:AP3) -> 230 | AR3: 35 | AS3: 7 | AX3: =SUM(AR3:AW3) -> 42 | AY3: 54 | AZ3: 11 | BC3: 1 | BE3: =SUM(AY3:BD3) -> 66 | BF3: 2 | BL3: =SUM(BF3:BK3) -> 2 | BM3: 75 | BN3: 7 | BS3: =SUM(BM3:BR3) -> 82 | BT3: 65 | BU3: 10 | BZ3: =SUM(BT3:BY3) -> 75 | CG3: =SUM(CA3:CF3) -> 0 | CH3: 67 | CI3: 6 | CN3: =SUM(CH3:CM3) -> 73 | CO3: 138 | CP3: 15 | CQ3: 3 | CS3: 5 | CU3: =SUM(CO3:CT3) -> 161 | DB3: =SUM(CV3:DA3) -> 0 | DI3: =SUM(DC3:DH3) -> 0 | DP3: =SUM(DJ3:DO3) -> 0 | DW3: =SUM(DQ3:DV3) -> 0 | ED3: =SUM(DX3:EC3) -> 0 | ER3: =SUM(EL3:EQ3) -> 0 | EY3: =SUM(ES3:EX3) -> 0 | FF3: =SUM(EZ3:FE3) -> 0 | FT3: =SUM(FN3:FS3) -> 0 | GA3: =SUM(FU3:FZ3) -> 0 | GH3: =SUM(GB3:GG3) -> 0 | GV3: =SUM(GP3:GU3) -> 0 | HC3: =SUM(GW3:HB3) -> 0 | HJ3: =SUM(HD3:HI3) -> 0
A4: 7.15-7.30 | B4: 44 | C4: 4 | G4: 1 | H4: =SUM(B4:G4) -> 49 | I4: 27 | J4: 4 | O4: =SUM(I4:N4) -> 31 | P4: 30 | Q4: 3 | V4: =SUM(P4:U4) -> 33 | AC4: =SUM(W4:AB4) -> 0 | AD4: 51 | AE4: 14 | AJ4: =SUM(AD4:AI4) -> 65 | AK4: 180 | AL4: 24 | AO4: 7 | AQ4: =SUM(AK4:AP4) -> 211 | AR4: 26 | AS4: 3 | AX4: =SUM(AR4:AW4) -> 29 | AY4: 61 | AZ4: 13 | BE4: =SUM(AY4:BD4) -> 74 | BF4: 2 | BL4: =SUM(BF4:BK4) -> 2 | BM4: 68 | BN4: 9 | BS4: =SUM(BM4:BR4) -> 77 | BT4: 49 | BU4: 8 | BZ4: =SUM(BT4:BY4) -> 57 | CG4: =SUM(CA4:CF4) -> 0 | CH4: 56 | CI4: 3 | CL4: 1 | CN4: =SUM(CH4:CM4) -> 60 | CO4: 146 | CP4: 21 | CQ4: 2 | CS4: 3 | CU4: =SUM(CO4:CT4) -> 172 | DB4: =SUM(CV4:DA4) -> 0 | DI4: =SUM(DC4:DH4) -> 0 | DP4: =SUM(DJ4:DO4) -> 0 | DW4: =SUM(DQ4:DV4) -> 0 | ED4: =SUM(DX4:EC4) -> 0 | ER4: =SUM(EL4:EQ4) -> 0 | EY4: =SUM(ES4:EX4) -> 0 | FF4: =SUM(EZ4:FE4) -> 0 | FT4: =SUM(FN4:FS4) -> 0 | GA4: =SUM(FU4:FZ4) -> 0 | GH4: =SUM(GB4:GG4) -> 0 | GV4: =SUM(GP4:GU4) -> 0 | HC4: =SUM(GW4:HB4) -> 0 | HJ4: =SUM(HD4:HI4) -> 0
A5: 7.30-7.45 | B5: 41 | C5: 9 | F5: 2 | H5: =SUM(B5:G5) -> 52 | I5: 21 | J5: 9 | O5: =SUM(I5:N5) -> 30 | P5: 27 | Q5: 5 | V5: =SUM(P5:U5) -> 32 | AC5: =SUM(W5:AB5) -> 0 | AD5: 43 | AE5: 16 | AJ5: =SUM(AD5:AI5) -> 59 | AK5: 177 | AL5: 41 | AM5: 1 | AN5: 1 | AO5: 2 | AQ5: =SUM(AK5:AP5) -> 222 | AR5: 31 | AS5: 9 | AX5: =SUM(AR5:AW5) -> 40 | AY5: 57 | AZ5: 17 | BE5: =SUM(AY5:BD5) -> 74 | BF5: 3 | BG5: 1 | BL5: =SUM(BF5:BK5) -> 4 | BM5: 70 | BN5: 13 | BQ5: 1 | BS5: =SUM(BM5:BR5) -> 84 | BT5: 60 | BU5: 12 | BZ5: =SUM(BT5:BY5) -> 72 | CG5: =SUM(CA5:CF5) -> 0 | CH5: 52 | CI5: 5 | CN5: =SUM(CH5:CM5) -> 57 | CO5: 153 | CP5: 23 | CQ5: 1 | CS5: 1 | CU5: =SUM(CO5:CT5) -> 178 | DB5: =SUM(CV5:DA5) -> 0 | DI5: =SUM(DC5:DH5) -> 0 | DP5: =SUM(DJ5:DO5) -> 0 | DW5: =SUM(DQ5:DV5) -> 0 | ED5: =SUM(DX5:EC5) -> 0 | ER5: =SUM(EL5:EQ5) -> 0 | EY5: =SUM(ES5:EX5) -> 0 | FF5: =SUM(EZ5:FE5) -> 0 | FT5: =SUM(FN5:FS5) -> 0 | GA5: =SUM(FU5:FZ5) -> 0 | GH5: =SUM(GB5:GG5) -> 0 | GV5: =SUM(GP5:GU5) -> 0 | HC5: =SUM(GW5:HB5) -> 0 | HJ5: =SUM(HD5:HI5) -> 0
A6: 7.45-8.00 | B6: 56 | C6: 5 | H6: =SUM(B6:G6) -> 61 | I6: 18 | J6: 11 | O6: =SUM(I6:N6) -> 29 | P6: 18 | Q6: 6 | V6: =SUM(P6:U6) -> 24 | AC6: =SUM(W6:AB6) -> 0 | AD6: 48 | AE6: 10 | AJ6: =SUM(AD6:AI6) -> 58 | AK6: 168 | AL6: 37 | AO6: 4 | AQ6: =SUM(AK6:AP6) -> 209 | AR6: 23 | AS6: 5 | AX6: =SUM(AR6:AW6) -> 28 | AY6: 66 | AZ6: 12 | BA6: 1 | BC6: 2 | BE6: =SUM(AY6:BD6) -> 81 | BF6: 6 | BG6: 2 | BL6: =SUM(BF6:BK6) -> 8 | BM6: 62 | BN6: 8 | BS6: =SUM(BM6:BR6) -> 70 | BT6: 55 | BU6: 9 | BZ6: =SUM(BT6:BY6) -> 64 | CG6: =SUM(CA6:CF6) -> 0 | CH6: 60 | CI6: 7 | CN6: =SUM(CH6:CM6) -> 67 | CO6: 150 | CP6: 25 | CQ6: 1 | CS6: 2 | CU6: =SUM(CO6:CT6) -> 178 | DB6: =SUM(CV6:DA6) -> 0 | DI6: =SUM(DC6:DH6) -> 0 | DP6: =SUM(DJ6:DO6) -> 0 | DW6: =SUM(DQ6:DV6) -> 0 | ED6: =SUM(DX6:EC6) -> 0 | ER6: =SUM(EL6:EQ6) -> 0 | EY6: =SUM(ES6:EX6) -> 0 | FF6: =SUM(EZ6:FE6) -> 0 | FT6: =SUM(FN6:FS6) -> 0 | GA6: =SUM(FU6:FZ6) -> 0 | GH6: =SUM(GB6:GG6) -> 0 | GV6: =SUM(GP6:GU6) -> 0 | HC6: =SUM(GW6:HB6) -> 0 | HJ6: =SUM(HD6:HI6) -> 0
A7: 8.00-8.15 | B7: 52 | C7: 5 | D7: 1 | G7: 2 | H7: =SUM(B7:G7) -> 60 | I7: 19 | J7: 8 | O7: =SUM(I7:N7) -> 27 | P7: 15 | Q7: 9 | V7: =SUM(P7:U7) -> 24 | AC7: =SUM(W7:AB7) -> 0 | AD7: 45 | AE7: 14 | AJ7: =SUM(AD7:AI7) -> 59 | AK7: 154 | AL7: 48 | AM7: 2 | AO7: 2 | AQ7: =SUM(AK7:AP7) -> 206 | AR7: 38 | AS7: 8 | AX7: =SUM(AR7:AW7) -> 46 | AY7: 60 | AZ7: 16 | BC7: 1 | BD7: 1 | BE7: =SUM(AY7:BD7) -> 78 | BF7: 2 | BG7: 2 | BL7: =SUM(BF7:BK7) -> 4 | BM7: 58 | BN7: 10 | BS7: =SUM(BM7:BR7) -> 68 | BT7: 63 | BU7: 17 | BZ7: =SUM(BT7:BY7) -> 80 | CG7: =SUM(CA7:CF7) -> 0 | CH7: 69 | CI7: 10 | CL7: 1 | CN7: =SUM(CH7:CM7) -> 80 | CO7: 142 | CP7: 18 | CQ7: 2 | CS7: 2 | CU7: =SUM(CO7:CT7) -> 164 | DB7: =SUM(CV7:DA7) -> 0 | DI7: =SUM(DC7:DH7) -> 0 | DP7: =SUM(DJ7:DO7) -> 0 | DW7: =SUM(DQ7:DV7) -> 0 | ED7: =SUM(DX7:EC7) -> 0 | ER7: =SUM(EL7:EQ7) -> 0 | EY7: =SUM(ES7:EX7) -> 0 | FF7: =SUM(EZ7:FE7) -> 0 | FT7: =SUM(FN7:FS7) -> 0 | GA7: =SUM(FU7:FZ7) -> 0 | GH7: =SUM(GB7:GG7) -> 0 | GV7: =SUM(GP7:GU7) -> 0 | HC7: =SUM(GW7:HB7) -> 0 | HJ7: =SUM(HD7:HI7) -> 0
A8: 8.15-8.30 | B8: 47 | C8: 8 | F8: 1 | H8: =SUM(B8:G8) -> 56 | I8: 23 | J8: 2 | O8: =SUM(I8:N8) -> 25 | P8: 23 | Q8: 4 | V8: =SUM(P8:U8) -> 27 | AC8: =SUM(W8:AB8) -> 0 | AD8: 39 | AE8: 11 | AH8: 1 | AJ8: =SUM(AD8:AI8) -> 51 | AK8: 147 | AL8: 55 | AO8: 6 | AQ8: =SUM(AK8:AP8) -> 208 | AR8: 30 | AS8: 4 | AV8: 1 | AW8: 1 | AX8: =SUM(AR8:AW8) -> 36 | AY8: 58 | AZ8: 13 | BD8: 2 | BE8: =SUM(AY8:BD8) -> 73 | BF8: 1 | BG8: 3 | BL8: =SUM(BF8:BK8) -> 4 | BM8: 60 | BN8: 14 | BS8: =SUM(BM8:BR8) -> 74 | BT8: 76 | BU8: 24 | BZ8: =SUM(BT8:BY8) -> 100 | CG8: =SUM(CA8:CF8) -> 0 | CH8: 58 | CI8: 8 | CN8: =SUM(CH8:CM8) -> 66 | CO8: 138 | CP8: 12 | CS8: 3 | CU8: =SUM(CO8:CT8) -> 153 | DB8: =SUM(CV8:DA8) -> 0 | DI8: =SUM(DC8:DH8) -> 0 | DP8: =SUM(DJ8:DO8) -> 0 | DW8: =SUM(DQ8:DV8) -> 0 | ED8: =SUM(DX8:EC8) -> 0 | ER8: =SUM(EL8:EQ8) -> 0 | EY8: =SUM(ES8:EX8) -> 0 | FF8: =SUM(EZ8:FE8) -> 0 | FT8: =SUM(FN8:FS8) -> 0 | GA8: =SUM(FU8:FZ8) -> 0 | GH8: =SUM(GB8:GG8) -> 0 | GV8: =SUM(GP8:GU8) -> 0 | HC8: =SUM(GW8:HB8) -> 0 | HJ8: =SUM(HD8:HI8) -> 0
A9: 8.30-8.45 | B9: 41 | C9: 4 | F9: 1 | H9: =SUM(B9:G9) -> 46 | I9: 14 | J9: 13 | O9: =SUM(I9:N9) -> 27 | P9: 21 | Q9: 6 | V9: =SUM(P9:U9) -> 27 | AC9: =SUM(W9:AB9) -> 0 | AD9: 44 | AE9: 16 | AJ9: =SUM(AD9:AI9) -> 60 | AK9: 138 | AL9: 43 | AO9: 6 | AP9: 1 | AQ9: =SUM(AK9:AP9) -> 188 | AR9: 42 | AS9: 6 | AX9: =SUM(AR9:AW9) -> 48 | AY9: 53 | AZ9: 19 | BC9: 3 | BE9: =SUM(AY9:BD9) -> 75 | BF9: 4 | BL9: =SUM(BF9:BK9) -> 4 | BM9: 50 | BN9: 11 | BO9: 1 | BQ9: 1 | BS9: =SUM(BM9:BR9) -> 63 | BT9: 59 | BU9: 12 | BZ9: =SUM(BT9:BY9) -> 71 | CG9: =SUM(CA9:CF9) -> 0 | CH9: 64 | CI9: 12 | CN9: =SUM(CH9:CM9) -> 76 | CO9: 125 | CP9: 15 | CR9: 1 | CS9: 5 | CU9: =SUM(CO9:CT9) -> 146 | DB9: =SUM(CV9:DA9) -> 0 | DI9: =SUM(DC9:DH9) -> 0 | DP9: =SUM(DJ9:DO9) -> 0 | DW9: =SUM(DQ9:DV9) -> 0 | ED9: =SUM(DX9:EC9) -> 0 | ER9: =SUM(EL9:EQ9) -> 0 | EY9: =SUM(ES9:EX9) -> 0 | FF9: =SUM(EZ9:FE9) -> 0 | FT9: =SUM(FN9:FS9) -> 0 | GA9: =SUM(FU9:FZ9) -> 0 | GH9: =SUM(GB9:GG9) -> 0 | GV9: =SUM(GP9:GU9) -> 0 | HC9: =SUM(GW9:HB9) -> 0 | HJ9: =SUM(HD9:HI9) -> 0
A10: 8.45-9.00 | B10: 45 | C10: 4 | H10: =SUM(B10:G10) -> 49 | I10: 25 | J10: 7 | O10: =SUM(I10:N10) -> 32 | P10: 16 | Q10: 8 | V10: =SUM(P10:U10) -> 24 | AC10: =SUM(W10:AB10) -> 0 | AD10: 41 | AE10: 12 | AJ10: =SUM(AD10:AI10) -> 53 | AK10: 163 | AL10: 52 | AM10: 1 | AO10: 4 | AQ10: =SUM(AK10:AP10) -> 220 | AR10: 36 | AS10: 3 | AV10: 2 | AX10: =SUM(AR10:AW10) -> 41 | AY10: 51 | AZ10: 11 | BC10: 1 | BE10: =SUM(AY10:BD10) -> 63 | BF10: 7 | BL10: =SUM(BF10:BK10) -> 7 | BM10: 48 | BN10: 16 | BQ10: 1 | BS10: =SUM(BM10:BR10) -> 65 | BT10: 65 | BU10: 20 | BZ10: =SUM(BT10:BY10) -> 85 | CG10: =SUM(CA10:CF10) -> 0 | CH10: 52 | CI10: 5 | CL10: 2 | CN10: =SUM(CH10:CM10) -> 59 | CO10: 130 | CP10: 17 | CQ10: 1 | CS10: 2 | CU10: =SUM(CO10:CT10) -> 150 | DB10: =SUM(CV10:DA10) -> 0 | DI10: =SUM(DC10:DH10) -> 0 | DP10: =SUM(DJ10:DO10) -> 0 | DW10: =SUM(DQ10:DV10) -> 0 | ED10: =SUM(DX10:EC10) -> 0 | ER10: =SUM(EL10:EQ10) -> 0 | EY10: =SUM(ES10:EX10) -> 0 | FF10: =SUM(EZ10:FE10) -> 0 | FT10: =SUM(FN10:FS10) -> 0 | GA10: =SUM(FU10:FZ10) -> 0 | GH10: =SUM(GB10:GG10) -> 0 | GV10: =SUM(GP10:GU10) -> 0 | HC10: =SUM(GW10:HB10) -> 0 | HJ10: =SUM(HD10:HI10) -> 0
A11: 9.00-9.15 | B11: 38 | C11: 6 | F11: 2 | H11: =SUM(B11:G11) -> 46 | I11: 48 | J11: 11 | O11: =SUM(I11:N11) -> 59 | P11: 17 | Q11: 8 | V11: =SUM(P11:U11) -> 25 | AC11: =SUM(W11:AB11) -> 0 | AD11: 36 | AE11: 9 | AJ11: =SUM(AD11:AI11) -> 45 | AK11: 170 | AL11: 44 | AO11: 6 | AQ11: =SUM(AK11:AP11) -> 220 | AR11: 45 | AS11: 7 | AV11: 1 | AX11: =SUM(AR11:AW11) -> 53 | AY11: 47 | AZ11: 14 | BC11: 2 | BE11: =SUM(AY11:BD11) -> 63 | BF11: 3 | BG11: 1 | BL11: =SUM(BF11:BK11) -> 4 | BM11: 58 | BN11: 11 | BQ11: 1 | BS11: =SUM(BM11:BR11) -> 70 | BT11: 70 | BU11: 10 | BZ11: =SUM(BT11:BY11) -> 80 | CG11: =SUM(CA11:CF11) -> 0 | CH11: 59 | CI11: 9 | CL11: 1 | CN11: =SUM(CH11:CM11) -> 69 | CO11: 122 | CP11: 23 | CS11: 1 | CU11: =SUM(CO11:CT11) -> 146 | DB11: =SUM(CV11:DA11) -> 0 | DI11: =SUM(DC11:DH11) -> 0 | DP11: =SUM(DJ11:DO11) -> 0 | DW11: =SUM(DQ11:DV11) -> 0 | ED11: =SUM(DX11:EC11) -> 0 | ER11: =SUM(EL11:EQ11) -> 0 | EY11: =SUM(ES11:EX11) -> 0 | FF11: =SUM(EZ11:FE11) -> 0 | FT11: =SUM(FN11:FS11) -> 0 | GA11: =SUM(FU11:FZ11) -> 0 | GH11: =SUM(GB11:GG11) -> 0 | GV11: =SUM(GP11:GU11) -> 0 | HC11: =SUM(GW11:HB11) -> 0 | HJ11: =SUM(HD11:HI11) -> 0
A12: 9.15-9.30 | B12: 42 | C12: 5 | G12: 1 | H12: =SUM(B12:G12) -> 48 | I12: 57 | J12: 8 | O12: =SUM(I12:N12) -> 65 | P12: 19 | Q12: 7 | T12: 1 | V12: =SUM(P12:U12) -> 27 | AC12: =SUM(W12:AB12) -> 0 | AD12: 42 | AE12: 12 | AJ12: =SUM(AD12:AI12) -> 54 | AK12: 149 | AL12: 36 | AO12: 2 | AQ12: =SUM(AK12:AP12) -> 187 | AR12: 33 | AS12: 10 | AV12: 3 | AX12: =SUM(AR12:AW12) -> 46 | AY12: 52 | AZ12: 17 | BA12: 1 | BD12: 1 | BE12: =SUM(AY12:BD12) -> 71 | BF12: 5 | BG12: 4 | BL12: =SUM(BF12:BK12) -> 9 | BM12: 45 | BN12: 16 | BS12: =SUM(BM12:BR12) -> 61 | BT12: 47 | BU12: 14 | BZ12: =SUM(BT12:BY12) -> 61 | CG12: =SUM(CA12:CF12) -> 0 | CH12: 46 | CI12: 11 | CN12: =SUM(CH12:CM12) -> 57 | CO12: 118 | CP12: 20 | CQ12: 1 | CS12: 2 | CU12: =SUM(CO12:CT12) -> 141 | DB12: =SUM(CV12:DA12) -> 0 | DI12: =SUM(DC12:DH12) -> 0 | DP12: =SUM(DJ12:DO12) -> 0 | DW12: =SUM(DQ12:DV12) -> 0 | ED12: =SUM(DX12:EC12) -> 0 | ER12: =SUM(EL12:EQ12) -> 0 | EY12: =SUM(ES12:EX12) -> 0 | FF12: =SUM(EZ12:FE12) -> 0 | FT12: =SUM(FN12:FS12) -> 0 | GA12: =SUM(FU12:FZ12) -> 0 | GH12: =SUM(GB12:GG12) -> 0 | GV12: =SUM(GP12:GU12) -> 0 | HC12: =SUM(GW12:HB12) -> 0 | HJ12: =SUM(HD12:HI12) -> 0
A13: 9.30-9.45 | B13: 37 | C13: 9 | H13: =SUM(B13:G13) -> 46 | I13: 66 | J13: 6 | O13: =SUM(I13:N13) -> 72 | P13: 21 | Q13: 10 | V13: =SUM(P13:U13) -> 31 | AC13: =SUM(W13:AB13) -> 0 | AD13: 38 | AE13: 8 | AJ13: =SUM(AD13:AI13) -> 46 | AK13: 151 | AL13: 51 | AN13: 1 | AO13: 9 | AQ13: =SUM(AK13:AP13) -> 212 | AR13: 39 | AS13: 6 | AW13: 1 | AX13: =SUM(AR13:AW13) -> 46 | AY13: 55 | AZ13: 23 | BC13: 1 | BE13: =SUM(AY13:BD13) -> 79 | BF13: 2 | BJ13: 1 | BL13: =SUM(BF13:BK13) -> 3 | BM13: 65 | BN13: 18 | BS13: =SUM(BM13:BR13) -> 83 | BT13: 52 | BU13: 22 | BZ13: =SUM(BT13:BY13) -> 74 | CG13: =SUM(CA13:CF13) -> 0 | CH13: 50 | CI13: 8 | CN13: =SUM(CH13:CM13) -> 58 | CO13: 105 | CP13: 28 | CR13: 1 | CS13: 2 | CU13: =SUM(CO13:CT13) -> 136 | DB13: =SUM(CV13:DA13) -> 0 | DI13: =SUM(DC13:DH13) -> 0 | DP13: =SUM(DJ13:DO13) -> 0 | DW13: =SUM(DQ13:DV13) -> 0 | ED13: =SUM(DX13:EC13) -> 0 | ER13: =SUM(EL13:EQ13) -> 0 | EY13: =SUM(ES13:EX13) -> 0 | FF13: =SUM(EZ13:FE13) -> 0 | FT13: =SUM(FN13:FS13) -> 0 | GA13: =SUM(FU13:FZ13) -> 0 | GH13: =SUM(GB13:GG13) -> 0 | GV13: =SUM(GP13:GU13) -> 0 | HC13: =SUM(GW13:HB13) -> 0 | HJ13: =SUM(HD13:HI13) -> 0
A14: 9.45-10.00 | B14: 31 | C14: 10 | F14: 1 | H14: =SUM(B14:G14) -> 42 | I14: 41 | J14: 13 | O14: =SUM(I14:N14) -> 54 | P14: 18 | Q14: 6 | V14: =SUM(P14:U14) -> 24 | AC14: =SUM(W14:AB14) -> 0 | AD14: 41 | AE14: 16 | AJ14: =SUM(AD14:AI14) -> 57 | AK14: 135 | AL14: 48 | AM14: 1 | AO14: 6 | AQ14: =SUM(AK14:AP14) -> 190 | AR14: 30 | AS14: 9 | AV14: 1 | AX14: =SUM(AR14:AW14) -> 40 | AY14: 44 | AZ14: 15 | BC14: 1 | BE14: =SUM(AY14:BD14) -> 60 | BF14: 6 | BG14: 2 | BL14: =SUM(BF14:BK14) -> 8 | BM14: 58 | BN14: 12 | BQ14: 1 | BS14: =SUM(BM14:BR14) -> 71 | BT14: 36 | BU14: 10 | BZ14: =SUM(BT14:BY14) -> 46 | CG14: =SUM(CA14:CF14) -> 0 | CH14: 42 | CI14: 5 | CL14: 1 | CN14: =SUM(CH14:CM14) -> 48 | CO14: 110 | CP14: 22 | CQ14: 2 | CS14: 1 | CU14: =SUM(CO14:CT14) -> 135 | DB14: =SUM(CV14:DA14) -> 0 | DI14: =SUM(DC14:DH14) -> 0 | DP14: =SUM(DJ14:DO14) -> 0 | DW14: =SUM(DQ14:DV14) -> 0 | ED14: =SUM(DX14:EC14) -> 0 | ER14: =SUM(EL14:EQ14) -> 0 | EY14: =SUM(ES14:EX14) -> 0 | FF14: =SUM(EZ14:FE14) -> 0 | FT14: =SUM(FN14:FS14) -> 0 | GA14: =SUM(FU14:FZ14) -> 0 | GH14: =SUM(GB14:GG14) -> 0 | GV14: =SUM(GP14:GU14) -> 0 | HC14: =SUM(GW14:HB14) -> 0 | HJ14: =SUM(HD14:HI14) -> 0
A15: 10.00-10.15 | B15: 34 | C15: 7 | G15: 3 | H15: =SUM(B15:G15) -> 44 | I15: 38 | J15: 5 | O15: =SUM(I15:N15) -> 43 | P15: 27 | Q15: 12 | V15: =SUM(P15:U15) -> 39 | AC15: =SUM(W15:AB15) -> 0 | AD15: 44 | AE15: 18 | AJ15: =SUM(AD15:AI15) -> 62 | AK15: 122 | AL15: 36 | AM15: 1 | AO15: 7 | AQ15: =SUM(AK15:AP15) -> 166 | AR15: 24 | AS15: 8 | AX15: =SUM(AR15:AW15) -> 32 | AY15: 47 | AZ15: 24 | BD15: 2 | BE15: =SUM(AY15:BD15) -> 73 | BF15: 4 | BL15: =SUM(BF15:BK15) -> 4 | BM15: 58 | BN15: 14 | BS15: =SUM(BM15:BR15) -> 72 | BT15: 50 | BU15: 13 | BZ15: =SUM(BT15:BY15) -> 63 | CG15: =SUM(CA15:CF15) -> 0 | CH15: 35 | CI15: 9 | CL15: 2 | CN15: =SUM(CH15:CM15) -> 46 | CO15: 112 | CP15: 25 | CQ15: 1 | CS15: 1 | CT15: 1 | CU15: =SUM(CO15:CT15) -> 140 | DB15: =SUM(CV15:DA15) -> 0 | DI15: =SUM(DC15:DH15) -> 0 | DP15: =SUM(DJ15:DO15) -> 0 | DW15: =SUM(DQ15:DV15) -> 0 | ED15: =SUM(DX15:EC15) -> 0 | ER15: =SUM(EL15:EQ15) -> 0 | EY15: =SUM(ES15:EX15) -> 0 | FF15: =SUM(EZ15:FE15) -> 0 | FT15: =SUM(FN15:FS15) -> 0 | GA15: =SUM(FU15:FZ15) -> 0 | GH15: =SUM(GB15:GG15) -> 0 | GV15: =SUM(GP15:GU15) -> 0 | HC15: =SUM(GW15:HB15) -> 0 | HJ15: =SUM(HD15:HI15) -> 0
A16: 10.15-10.30 | B16: 26 | C16: 4 | H16: =SUM(B16:G16) -> 30 | I16: 53 | J16: 12 | O16: =SUM(I16:N16) -> 65 | P16: 30 | Q16: 8 | V16: =SUM(P16:U16) -> 38 | AC16: =SUM(W16:AB16) -> 0 | AD16: 52 | AE16: 22 | AF16: 1 | AJ16: =SUM(AD16:AI16) -> 75 | AK16: 119 | AL16: 52 | AO16: 5 | AQ16: =SUM(AK16:AP16) -> 176 | AR16: 18 | AS16: 5 | AV16: 1 | AX16: =SUM(AR16:AW16) -> 24 | AY16: 41 | AZ16: 21 | BC16: 3 | BE16: =SUM(AY16:BD16) -> 65 | BF16: 3 | BL16: =SUM(BF16:BK16) -> 3 | BM16: 63 | BN16: 10 | BQ16: 2 | BS16: =SUM(BM16:BR16) -> 75 | BT16: 72 | BU16: 9 | BZ16: =SUM(BT16:BY16) -> 81 | CG16: =SUM(CA16:CF16) -> 0 | CH16: 20 | CI16: 6 | CN16: =SUM(CH16:CM16) -> 26 | CO16: 108 | CP16: 18 | CS16: 3 | CU16: =SUM(CO16:CT16) -> 129 | DB16: =SUM(CV16:DA16) -> 0 | DI16: =SUM(DC16:DH16) -> 0 | DP16: =SUM(DJ16:DO16) -> 0 | DW16: =SUM(DQ16:DV16) -> 0 | ED16: =SUM(DX16:EC16) -> 0 | ER16: =SUM(EL16:EQ16) -> 0 | EY16: =SUM(ES16:EX16) -> 0 | FF16: =SUM(EZ16:FE16) -> 0 | FT16: =SUM(FN16:FS16) -> 0 | GA16: =SUM(FU16:FZ16) -> 0 | GH16: =SUM(GB16:GG16) -> 0 | GV16: =SUM(GP16:GU16) -> 0 | HC16: =SUM(GW16:HB16) -> 0 | HJ16: =SUM(HD16:HI16) -> 0
A17: 10.30-10.45 | B17: 29 | C17: 8 | F17: 1 | H17: =SUM(B17:G17) -> 38 | I17: 46 | J17: 7 | O17: =SUM(I17:N17) -> 53 | P17: 26 | Q17: 11 | V17: =SUM(P17:U17) -> 37 | AC17: =SUM(W17:AB17) -> 0 | AD17: 49 | AE17: 19 | AJ17: =SUM(AD17:AI17) -> 68 | AK17: 137 | AL17: 49 | AO17: 8 | AQ17: =SUM(AK17:AP17) -> 194 | AR17: 27 | AS17: 10 | AV17: 1 | AX17: =SUM(AR17:AW17) -> 38 | AY17: 36 | AZ17: 16 | BE17: =SUM(AY17:BD17) -> 52 | BF17: 8 | BG17: 3 | BL17: =SUM(BF17:BK17) -> 11 | BM17: 51 | BN17: 15 | BS17: =SUM(BM17:BR17) -> 66 | BT17: 65 | BU17: 20 | BZ17: =SUM(BT17:BY17) -> 85 | CG17: =SUM(CA17:CF17) -> 0 | CH17: 28 | CI17: 10 | CL17: 1 | CN17: =SUM(CH17:CM17) -> 39 | CO17: 95 | CP17: 23 | CS17: 2 | CU17: =SUM(CO17:CT17) -> 120 | DB17: =SUM(CV17:DA17) -> 0 | DI17: =SUM(DC17:DH17) -> 0 | DP17: =SUM(DJ17:DO17) -> 0 | DW17: =SUM(DQ17:DV17) -> 0 | ED17: =SUM(DX17:EC17) -> 0 | ER17: =SUM(EL17:EQ17) -> 0 | EY17: =SUM(ES17:EX17) -> 0 | FF17: =SUM(EZ17:FE17) -> 0 | FT17: =SUM(FN17:FS17) -> 0 | GA17: =SUM(FU17:FZ17) -> 0 | GH17: =SUM(GB17:GG17) -> 0 | GV17: =SUM(GP17:GU17) -> 0 | HC17: =SUM(GW17:HB17) -> 0 | HJ17: =SUM(HD17:HI17) -> 0
A18: 10.45-11.00 | B18: 37 | C18: 5 | F18: 1 | H18: =SUM(B18:G18) -> 43 | I18: 51 | J18: 10 | O18: =SUM(I18:N18) -> 61 | P18: 19 | Q18: 9 | V18: =SUM(P18:U18) -> 28 | AC18: =SUM(W18:AB18) -> 0 | AD18: 55 | AE18: 26 | AF18: 1 | AJ18: =SUM(AD18:AI18) -> 82 | AK18: 146 | AL18: 51 | AN18: 1 | AO18: 4 | AQ18: =SUM(AK18:AP18) -> 202 | AR18: 20 | AS18: 7 | AX18: =SUM(AR18:AW18) -> 27 | AY18: 43 | AZ18: 19 | BC18: 1 | BE18: =SUM(AY18:BD18) -> 63 | BF18: 2 | BG18: 1 | BL18: =SUM(BF18:BK18) -> 3 | BM18: 48 | BN18: 16 | BQ18: 1 | BS18: =SUM(BM18:BR18) -> 65 | BT18: 59 | BU18: 12 | BZ18: =SUM(BT18:BY18) -> 71 | CG18: =SUM(CA18:CF18) -> 0 | CH18: 22 | CI18: 8 | CN18: =SUM(CH18:CM18) -> 30 | CO18: 102 | CP18: 20 | CQ18: 1 | CR18: 1 | CS18: 2 | CU18: =SUM(CO18:CT18) -> 126 | DB18: =SUM(CV18:DA18) -> 0 | DI18: =SUM(DC18:DH18) -> 0 | DP18: =SUM(DJ18:DO18) -> 0 | DW18: =SUM(DQ18:DV18) -> 0 | ED18: =SUM(DX18:EC18) -> 0 | ER18: =SUM(EL18:EQ18) -> 0 | EY18: =SUM(ES18:EX18) -> 0 | FF18: =SUM(EZ18:FE18) -> 0 | FT18: =SUM(FN18:FS18) -> 0 | GA18: =SUM(FU18:FZ18) -> 0 | GH18: =SUM(GB18:GG18) -> 0 | GV18: =SUM(GP18:GU18) -> 0 | HC18: =SUM(GW18:HB18) -> 0 | HJ18: =SUM(HD18:HI18) -> 0
A19: 11.00-11.15 | B19: 32 | C19: 5 | G19: 2 | H19: =SUM(B19:G19) -> 39 | I19: 46 | J19: 9 | O19: =SUM(I19:N19) -> 55 | P19: 22 | Q19: 7 | T19: 1 | V19: =SUM(P19:U19) -> 30 | AC19: =SUM(W19:AB19) -> 0 | AD19: 63 | AE19: 18 | AJ19: =SUM(AD19:AI19) -> 81 | AK19: 139 | AL19: 43 | AO19: 2 | AQ19: =SUM(AK19:AP19) -> 184 | AR19: 18 | AS19: 5 | AX19: =SUM(AR19:AW19) -> 23 | AY19: 35 | AZ19: 13 | BC19: 2 | BE19: =SUM(AY19:BD19) -> 50 | BF19: 5 | BL19: =SUM(BF19:BK19) -> 5 | BM19: 59 | BN19: 11 | BQ19: 1 | BS19: =SUM(BM19:BR19) -> 71 | BT19: 76 | BU19: 10 | BZ19: =SUM(BT19:BY19) -> 86 | CG19: =SUM(CA19:CF19) -> 0 | CH19: 15 | CI19: 5 | CM19: 1 | CN19: =SUM(CH19:CM19) -> 21 | CO19: 113 | CP19: 27 | CS19: 1 | CT19: 1 | CU19: =SUM(CO19:CT19) -> 142 | DB19: =SUM(CV19:DA19) -> 0 | DI19: =SUM(DC19:DH19) -> 0 | DP19: =SUM(DJ19:DO19) -> 0 | DW19: =SUM(DQ19:DV19) -> 0 | ED19: =SUM(DX19:EC19) -> 0 | ER19: =SUM(EL19:EQ19) -> 0 | EY19: =SUM(ES19:EX19) -> 0 | FF19: =SUM(EZ19:FE19) -> 0 | FT19: =SUM(FN19:FS19) -> 0 | GA19: =SUM(FU19:FZ19) -> 0 | GH19: =SUM(GB19:GG19) -> 0 | GV19: =SUM(GP19:GU19) -> 0 | HC19: =SUM(GW19:HB19) -> 0 | HJ19: =SUM(HD19:HI19) -> 0
A20: 11.15-11.30 | B20: 25 | C20: 9 | F20: 2 | H20: =SUM(B20:G20) -> 36 | I20: 61 | J20: 14 | O20: =SUM(I20:N20) -> 75 | P20: 28 | Q20: 4 | V20: =SUM(P20:U20) -> 32 | AC20: =SUM(W20:AB20) -> 0 | AD20: 54 | AE20: 24 | AJ20: =SUM(AD20:AI20) -> 78 | AK20: 127 | AL20: 54 | AO20: 5 | AQ20: =SUM(AK20:AP20) -> 186 | AR20: 23 | AS20: 11 | AX20: =SUM(AR20:AW20) -> 34 | AY20: 40 | AZ20: 23 | BC20: 2 | BD20: 1 | BE20: =SUM(AY20:BD20) -> 66 | BF20: 3 | BL20: =SUM(BF20:BK20) -> 3 | BM20: 62 | BN20: 14 | BS20: =SUM(BM20:BR20) -> 76 | BT20: 43 | BU20: 14 | BZ20: =SUM(BT20:BY20) -> 57 | CG20: =SUM(CA20:CF20) -> 0 | CH20: 20 | CI20: 9 | CL20: 1 | CN20: =SUM(CH20:CM20) -> 30 | CO20: 94 | CP20: 24 | CQ20: 2 | CS20: 1 | CU20: =SUM(CO20:CT20) -> 121 | DB20: =SUM(CV20:DA20) -> 0 | DI20: =SUM(DC20:DH20) -> 0 | DP20: =SUM(DJ20:DO20) -> 0 | DW20: =SUM(DQ20:DV20) -> 0 | ED20: =SUM(DX20:EC20) -> 0 | ER20: =SUM(EL20:EQ20) -> 0 | EY20: =SUM(ES20:EX20) -> 0 | FF20: =SUM(EZ20:FE20) -> 0 | FT20: =SUM(FN20:FS20) -> 0 | GA20: =SUM(FU20:FZ20) -> 0 | GH20: =SUM(GB20:GG20) -> 0 | GV20: =SUM(GP20:GU20) -> 0 | HC20: =SUM(GW20:HB20) -> 0 | HJ20: =SUM(HD20:HI20) -> 0
A21: 11.30-11.45 | B21: 29 | C21: 11 | G21: 1 | H21: =SUM(B21:G21) -> 41 | I21: 39 | J21: 8 | O21: =SUM(I21:N21) -> 47 | P21: 26 | Q21: 5 | V21: =SUM(P21:U21) -> 31 | AC21: =SUM(W21:AB21) -> 0 | AD21: 66 | AE21: 19 | AJ21: =SUM(AD21:AI21) -> 85 | AK21: 140 | AL21: 42 | AO21: 6 | AQ21: =SUM(AK21:AP21) -> 188 | AR21: 20 | AS21: 8 | AV21: 1 | AX21: =SUM(AR21:AW21) -> 29 | AY21: 32 | AZ21: 20 | BD21: 1 | BE21: =SUM(AY21:BD21) -> 53 | BF21: 2 | BG21: 2 | BL21: =SUM(BF21:BK21) -> 4 | BM21: 71 | BN21: 16 | BS21: =SUM(BM21:BR21) -> 87 | BT21: 59 | BU21: 9 | BZ21: =SUM(BT21:BY21) -> 68 | CG21: =SUM(CA21:CF21) -> 0 | CH21: 25 | CI21: 7 | CN21: =SUM(CH21:CM21) -> 32 | CO21: 97 | CP21: 20 | CR21: 1 | CS21: 3 | CU21: =SUM(CO21:CT21) -> 121 | DB21: =SUM(CV21:DA21) -> 0 | DI21: =SUM(DC21:DH21) -> 0 | DP21: =SUM(DJ21:DO21) -> 0 | DW21: =SUM(DQ21:DV21) -> 0 | ED21: =SUM(DX21:EC21) -> 0 | ER21: =SUM(EL21:EQ21) -> 0 | EY21: =SUM(ES21:EX21) -> 0 | FF21: =SUM(EZ21:FE21) -> 0 | FT21: =SUM(FN21:FS21) -> 0 | GA21: =SUM(FU21:FZ21) -> 0 | GH21: =SUM(GB21:GG21) -> 0 | GV21: =SUM(GP21:GU21) -> 0 | HC21: =SUM(GW21:HB21) -> 0 | HJ21: =SUM(HD21:HI21) -> 0
A22: 11.45-12.00 | B22: 30 | C22: 8 | H22: =SUM(B22:G22) -> 38 | I22: 54 | J22: 13 | N22: 1 | O22: =SUM(I22:N22) -> 68 | P22: 26 | Q22: 5 | V22: =SUM(P22:U22) -> 31 | AC22: =SUM(W22:AB22) -> 0 | AD22: 63 | AE22: 22 | AJ22: =SUM(AD22:AI22) -> 85 | AK22: 135 | AL22: 38 | AO22: 3 | AQ22: =SUM(AK22:AP22) -> 176 | AR22: 14 | AS22: 4 | AX22: =SUM(AR22:AW22) -> 18 | AY22: 39 | AZ22: 18 | BC22: 1 | BE22: =SUM(AY22:BD22) -> 58 | BF22: 3 | BG22: 1 | BJ22: 1 | BL22: =SUM(BF22:BK22) -> 5 | BM22: 68 | BN22: 13 | BQ22: 2 | BS22: =SUM(BM22:BR22) -> 83 | BT22: 44 | BU22: 10 | BZ22: =SUM(BT22:BY22) -> 54 | CG22: =SUM(CA22:CF22) -> 0 | CH22: 19 | CI22: 6 | CL22: 1 | CN22: =SUM(CH22:CM22) -> 26 | CO22: 105 | CP22: 18 | CS22: 2 | CU22: =SUM(CO22:CT22) -> 125 | DB22: =SUM(CV22:DA22) -> 0 | DI22: =SUM(DC22:DH22) -> 0 | DP22: =SUM(DJ22:DO22) -> 0 | DW22: =SUM(DQ22:DV22) -> 0 | ED22: =SUM(DX22:EC22) -> 0 | ER22: =SUM(EL22:EQ22) -> 0 | EY22: =SUM(ES22:EX22) -> 0 | FF22: =SUM(EZ22:FE22) -> 0 | FT22: =SUM(FN22:FS22) -> 0 | GA22: =SUM(FU22:FZ22) -> 0 | GH22: =SUM(GB22:GG22) -> 0 | GV22: =SUM(GP22:GU22) -> 0 | HC22: =SUM(GW22:HB22) -> 0 | HJ22: =SUM(HD22:HI22) -> 0
A23: 12.00-12.15 | B23: 26 | C23: 4 | F23: 1 | H23: =SUM(B23:G23) -> 31 | I23: 63 | J23: 17 | O23: =SUM(I23:N23) -> 80 | P23: 22 | Q23: 3 | V23: =SUM(P23:U23) -> 25 | AC23: =SUM(W23:AB23) -> 0 | AD23: 61 | AE23: 26 | AF23: 1 | AJ23: =SUM(AD23:AI23) -> 88 | AK23: 118 | AL23: 57 | AN23: 1 | AO23: 11 | AQ23: =SUM(AK23:AP23) -> 187 | AR23: 16 | AS23: 5 | AX23: =SUM(AR23:AW23) -> 21 | AY23: 45 | AZ23: 22 | BA23: 1 | BD23: 2 | BE23: =SUM(AY23:BD23) -> 70 | BF23: 7 | BL23: =SUM(BF23:BK23) -> 7 | BM23: 52 | BN23: 15 | BQ23: 1 | BS23: =SUM(BM23:BR23) -> 68 | BT23: 67 | BU23: 6 | BZ23: =SUM(BT23:BY23) -> 73 | CG23: =SUM(CA23:CF23) -> 0 | CH23: 16 | CI23: 4 | CL23: 1 | CN23: =SUM(CH23:CM23) -> 21 | CO23: 110 | CP23: 22 | CS23: 2 | CU23: =SUM(CO23:CT23) -> 134 | DB23: =SUM(CV23:DA23) -> 0 | DI23: =SUM(DC23:DH23) -> 0 | DP23: =SUM(DJ23:DO23) -> 0 | DW23: =SUM(DQ23:DV23) -> 0 | ED23: =SUM(DX23:EC23) -> 0 | ER23: =SUM(EL23:EQ23) -> 0 | EY23: =SUM(ES23:EX23) -> 0 | FF23: =SUM(EZ23:FE23) -> 0 | FT23: =SUM(FN23:FS23) -> 0 | GA23: =SUM(FU23:FZ23) -> 0 | GH23: =SUM(GB23:GG23) -> 0 | GV23: =SUM(GP23:GU23) -> 0 | HC23: =SUM(GW23:HB23) -> 0 | HJ23: =SUM(HD23:HI23) -> 0
A24: 12.15-12.30 | B24: 28 | C24: 6 | F24: 1 | H24: =SUM(B24:G24) -> 35 | I24: 55 | J24: 10 | O24: =SUM(I24:N24) -> 65 | P24: 18 | Q24: 7 | V24: =SUM(P24:U24) -> 25 | AC24: =SUM(W24:AB24) -> 0 | AD24: 64 | AE24: 23 | AJ24: =SUM(AD24:AI24) -> 87 | AK24: 124 | AL24: 32 | AO24: 9 | AQ24: =SUM(AK24:AP24) -> 165 | AR24: 19 | AS24: 9 | AX24: =SUM(AR24:AW24) -> 28 | AY24: 40 | AZ24: 15 | BC24: 3 | BE24: =SUM(AY24:BD24) -> 58 | BF24: 6 | BL24: =SUM(BF24:BK24) -> 6 | BM24: 65 | BN24: 14 | BS24: =SUM(BM24:BR24) -> 79 | BT24: 55 | BU24: 17 | BZ24: =SUM(BT24:BY24) -> 72 | CG24: =SUM(CA24:CF24) -> 0 | CH24: 24 | CI24: 10 | CN24: =SUM(CH24:CM24) -> 34 | CO24: 102 | CP24: 26 | CS24: 2 | CT24: 1 | CU24: =SUM(CO24:CT24) -> 131 | DB24: =SUM(CV24:DA24) -> 0 | DI24: =SUM(DC24:DH24) -> 0 | DP24: =SUM(DJ24:DO24) -> 0 | DW24: =SUM(DQ24:DV24) -> 0 | ED24: =SUM(DX24:EC24) -> 0 | ER24: =SUM(EL24:EQ24) -> 0 | EY24: =SUM(ES24:EX24) -> 0 | FF24: =SUM(EZ24:FE24) -> 0 | FT24: =SUM(FN24:FS24) -> 0 | GA24: =SUM(FU24:FZ24) -> 0 | GH24: =SUM(GB24:GG24) -> 0 | GV24: =SUM(GP24:GU24) -> 0 | HC24: =SUM(GW24:HB24) -> 0 | HJ24: =SUM(HD24:HI24) -> 0
A25: 12.30-12.45 | B25: 33 | C25: 5 | G25: 1 | H25: =SUM(B25:G25) -> 39 | I25: 48 | J25: 11 | O25: =SUM(I25:N25) -> 59 | P25: 25 | Q25: 2 | V25: =SUM(P25:U25) -> 27 | AC25: =SUM(W25:AB25) -> 0 | AD25: 58 | AE25: 19 | AJ25: =SUM(AD25:AI25) -> 77 | AK25: 131 | AL25: 43 | AM25: 1 | AO25: 6 | AQ25: =SUM(AK25:AP25) -> 181 | AR25: 22 | AS25: 6 | AX25: =SUM(AR25:AW25) -> 28 | AY25: 37 | AZ25: 22 | BC25: 3 | BE25: =SUM(AY25:BD25) -> 62 | BF25: 4 | BG25: 3 | BL25: =SUM(BF25:BK25) -> 7 | BM25: 59 | BN25: 10 | BQ25: 1 | BS25: =SUM(BM25:BR25) -> 70 | BT25: 43 | BU25: 8 | BZ25: =SUM(BT25:BY25) -> 51 | CG25: =SUM(CA25:CF25) -> 0 | CH25: 18 | CI25: 8 | CN25: =SUM(CH25:CM25) -> 26 | CO25: 95 | CP25: 24 | CQ25: 1 | CS25: 1 | CT25: 1 | CU25: =SUM(CO25:CT25) -> 122 | DB25: =SUM(CV25:DA25) -> 0 | DI25: =SUM(DC25:DH25) -> 0 | DP25: =SUM(DJ25:DO25) -> 0 | DW25: =SUM(DQ25:DV25) -> 0 | ED25: =SUM(DX25:EC25) -> 0 | ER25: =SUM(EL25:EQ25) -> 0 | EY25: =SUM(ES25:EX25) -> 0 | FF25: =SUM(EZ25:FE25) -> 0 | FT25: =SUM(FN25:FS25) -> 0 | GA25: =SUM(FU25:FZ25) -> 0 | GH25: =SUM(GB25:GG25) -> 0 | GV25: =SUM(GP25:GU25) -> 0 | HC25: =SUM(GW25:HB25) -> 0 | HJ25: =SUM(HD25:HI25) -> 0
A26: 12.45-13.00 | B26: 24 | C26: 8 | H26: =SUM(B26:G26) -> 32 | I26: 62 | J26: 14 | O26: =SUM(I26:N26) -> 76 | P26: 23 | Q26: 6 | V26: =SUM(P26:U26) -> 29 | AC26: =SUM(W26:AB26) -> 0 | AD26: 66 | AE26: 24 | AJ26: =SUM(AD26:AI26) -> 90 | AK26: 125 | AL26: 51 | AO26: 8 | AQ26: =SUM(AK26:AP26) -> 184 | AR26: 17 | AS26: 4 | AX26: =SUM(AR26:AW26) -> 21 | AY26: 41 | AZ26: 19 | BC26: 1 | BE26: =SUM(AY26:BD26) -> 61 | BF26: 4 | BL26: =SUM(BF26:BK26) -> 4 | BM26: 61 | BN26: 16 | BS26: =SUM(BM26:BR26) -> 77 | BT26: 66 | BU26: 13 | BZ26: =SUM(BT26:BY26) -> 79 | CG26: =SUM(CA26:CF26) -> 0 | CH26: 21 | CI26: 6 | CN26: =SUM(CH26:CM26) -> 27 | CO26: 91 | CP26: 22 | CS26: 1 | CU26: =SUM(CO26:CT26) -> 114 | DB26: =SUM(CV26:DA26) -> 0 | DI26: =SUM(DC26:DH26) -> 0 | DP26: =SUM(DJ26:DO26) -> 0 | DW26: =SUM(DQ26:DV26) -> 0 | ED26: =SUM(DX26:EC26) -> 0 | ER26: =SUM(EL26:EQ26) -> 0 | EY26: =SUM(ES26:EX26) -> 0 | FF26: =SUM(EZ26:FE26) -> 0 | FT26: =SUM(FN26:FS26) -> 0 | GA26: =SUM(FU26:FZ26) -> 0 | GH26: =SUM(GB26:GG26) -> 0 | GV26: =SUM(GP26:GU26) -> 0 | HC26: =SUM(GW26:HB26) -> 0 | HJ26: =SUM(HD26:HI26) -> 0
A27: 13.00-13.15 | B27: 29 | C27: 4 | H27: =SUM(B27:G27) -> 33 | I27: 49 | J27: 18 | M27: 1 | N27: 1 | O27: =SUM(I27:N27) -> 69 | P27: 20 | Q27: 11 | V27: =SUM(P27:U27) -> 31 | AC27: =SUM(W27:AB27) -> 0 | AD27: 53 | AE27: 22 | AJ27: =SUM(AD27:AI27) -> 75 | AK27: 138 | AL27: 48 | AM27: 1 | AO27: 9 | AQ27: =SUM(AK27:AP27) -> 196 | AR27: 21 | AS27: 4 | AX27: =SUM(AR27:AW27) -> 25 | AY27: 35 | AZ27: 18 | BC27: 1 | BE27: =SUM(AY27:BD27) -> 54 | BF27: 7 | BL27: =SUM(BF27:BK27) -> 7 | BM27: 53 | BN27: 14 | BQ27: 2 | BS27: =SUM(BM27:BR27) -> 69 | BT27: 73 | BU27: 13 | BZ27: =SUM(BT27:BY27) -> 86 | CG27: =SUM(CA27:CF27) -> 0 | CH27: 25 | CI27: 6 | CN27: =SUM(CH27:CM27) -> 31 | CO27: 104 | CP27: 25 | CS27: 3 | CT27: 1 | CU27: =SUM(CO27:CT27) -> 133 | DB27: =SUM(CV27:DA27) -> 0 | DI27: =SUM(DC27:DH27) -> 0 | DP27: =SUM(DJ27:DO27) -> 0 | DW27: =SUM(DQ27:DV27) -> 0 | ED27: =SUM(DX27:EC27) -> 0 | ER27: =SUM(EL27:EQ27) -> 0 | EY27: =SUM(ES27:EX27) -> 0 | FF27: =SUM(EZ27:FE27) -> 0 | FT27: =SUM(FN27:FS27) -> 0 | GA27: =SUM(FU27:FZ27) -> 0 | GH27: =SUM(GB27:GG27) -> 0 | GV27: =SUM(GP27:GU27) -> 0 | HC27: =SUM(GW27:HB27) -> 0 | HJ27: =SUM(HD27:HI27) -> 0
A28: 13.15-13.30 | B28: 22 | C28: 7 | F28: 1 | H28: =SUM(B28:G28) -> 30 | I28: 52 | J28: 14 | O28: =SUM(I28:N28) -> 66 | P28: 24 | Q28: 8 | V28: =SUM(P28:U28) -> 32 | AC28: =SUM(W28:AB28) -> 0 | AD28: 57 | AE28: 16 | AF28: 1 | AJ28: =SUM(AD28:AI28) -> 74 | AK28: 150 | AL28: 57 | AN28: 1 | AO28: 5 | AQ28: =SUM(AK28:AP28) -> 213 | AR28: 18 | AS28: 6 | AX28: =SUM(AR28:AW28) -> 24 | AY28: 47 | AZ28: 26 | BC28: 3 | BE28: =SUM(AY28:BD28) -> 76 | BF28: 3 | BL28: =SUM(BF28:BK28) -> 3 | BM28: 61 | BN28: 12 | BS28: =SUM(BM28:BR28) -> 73 | BT28: 78 | BU28: 10 | BZ28: =SUM(BT28:BY28) -> 88 | CG28: =SUM(CA28:CF28) -> 0 | CH28: 17 | CI28: 7 | CL28: 1 | CN28: =SUM(CH28:CM28) -> 25 | CO28: 119 | CP28: 19 | CQ28: 1 | CS28: 1 | CU28: =SUM(CO28:CT28) -> 140 | DB28: =SUM(CV28:DA28) -> 0 | DI28: =SUM(DC28:DH28) -> 0 | DP28: =SUM(DJ28:DO28) -> 0 | DW28: =SUM(DQ28:DV28) -> 0 | ED28: =SUM(DX28:EC28) -> 0 | ER28: =SUM(EL28:EQ28) -> 0 | EY28: =SUM(ES28:EX28) -> 0 | FF28: =SUM(EZ28:FE28) -> 0 | FT28: =SUM(FN28:FS28) -> 0 | GA28: =SUM(FU28:FZ28) -> 0 | GH28: =SUM(GB28:GG28) -> 0 | GV28: =SUM(GP28:GU28) -> 0 | HC28: =SUM(GW28:HB28) -> 0 | HJ28: =SUM(HD28:HI28) -> 0
A29: 13.30-13.45 | B29: 31 | C29: 5 | H29: =SUM(B29:G29) -> 36 | I29: 41 | J29: 15 | O29: =SUM(I29:N29) -> 56 | P29: 19 | Q29: 13 | T29: 2 | V29: =SUM(P29:U29) -> 34 | AC29: =SUM(W29:AB29) -> 0 | AD29: 49 | AE29: 13 | AJ29: =SUM(AD29:AI29) -> 62 | AK29: 136 | AL29: 60 | AO29: 5 | AP29: 1 | AQ29: =SUM(AK29:AP29) -> 202 | AR29: 20 | AS29: 6 | AV29: 1 | AX29: =SUM(AR29:AW29) -> 27 | AY29: 42 | AZ29: 15 | BE29: =SUM(AY29:BD29) -> 57 | BF29: 2 | BG29: 1 | BJ29: 1 | BL29: =SUM(BF29:BK29) -> 4 | BM29: 54 | BN29: 11 | BS29: =SUM(BM29:BR29) -> 65 | BT29: 52 | BU29: 5 | BZ29: =SUM(BT29:BY29) -> 57 | CG29: =SUM(CA29:CF29) -> 0 | CH29: 23 | CI29: 7 | CM29: 1 | CN29: =SUM(CH29:CM29) -> 31 | CO29: 88 | CP29: 26 | CQ29: 1 | CS29: 1 | CU29: =SUM(CO29:CT29) -> 116 | DB29: =SUM(CV29:DA29) -> 0 | DI29: =SUM(DC29:DH29) -> 0 | DP29: =SUM(DJ29:DO29) -> 0 | DW29: =SUM(DQ29:DV29) -> 0 | ED29: =SUM(DX29:EC29) -> 0 | ER29: =SUM(EL29:EQ29) -> 0 | EY29: =SUM(ES29:EX29) -> 0 | FF29: =SUM(EZ29:FE29) -> 0 | FT29: =SUM(FN29:FS29) -> 0 | GA29: =SUM(FU29:FZ29) -> 0 | GH29: =SUM(GB29:GG29) -> 0 | GV29: =SUM(GP29:GU29) -> 0 | HC29: =SUM(GW29:HB29) -> 0 | HJ29: =SUM(HD29:HI29) -> 0
A30: 13.45-14.00 | B30: 26 | C30: 5 | G30: 1 | H30: =SUM(B30:G30) -> 32 | I30: 37 | J30: 10 | O30: =SUM(I30:N30) -> 47 | P30: 23 | Q30: 5 | V30: =SUM(P30:U30) -> 28 | AC30: =SUM(W30:AB30) -> 0 | AD30: 41 | AE30: 18 | AJ30: =SUM(AD30:AI30) -> 59 | AK30: 162 | AL30: 42 | AM30: 1 | AO30: 6 | AQ30: =SUM(AK30:AP30) -> 211 | AR30: 15 | AS30: 5 | AX30: =SUM(AR30:AW30) -> 20 | AY30: 63 | AZ30: 17 | BC30: 2 | BD30: 1 | BE30: =SUM(AY30:BD30) -> 83 | BF30: 6 | BL30: =SUM(BF30:BK30) -> 6 | BM30: 50 | BN30: 15 | BQ30: 1 | BS30: =SUM(BM30:BR30) -> 66 | BT30: 65 | BU30: 15 | BZ30: =SUM(BT30:BY30) -> 80 | CG30: =SUM(CA30:CF30) -> 0 | CH30: 20 | CI30: 6 | CN30: =SUM(CH30:CM30) -> 26 | CO30: 94 | CP30: 24 | CS30: 2 | CT30: 2 | CU30: =SUM(CO30:CT30) -> 122 | DB30: =SUM(CV30:DA30) -> 0 | DI30: =SUM(DC30:DH30) -> 0 | DP30: =SUM(DJ30:DO30) -> 0 | DW30: =SUM(DQ30:DV30) -> 0 | ED30: =SUM(DX30:EC30) -> 0 | ER30: =SUM(EL30:EQ30) -> 0 | EY30: =SUM(ES30:EX30) -> 0 | FF30: =SUM(EZ30:FE30) -> 0 | FT30: =SUM(FN30:FS30) -> 0 | GA30: =SUM(FU30:FZ30) -> 0 | GH30: =SUM(GB30:GG30) -> 0 | GV30: =SUM(GP30:GU30) -> 0 | HC30: =SUM(GW30:HB30) -> 0 | HJ30: =SUM(HD30:HI30) -> 0
A31: 14.00-14.15 | B31: 37 | C31: 9 | F31: 1 | H31: =SUM(B31:G31) -> 47 | I31: 38 | J31: 8 | O31: =SUM(I31:N31) -> 46 | P31: 21 | Q31: 10 | V31: =SUM(P31:U31) -> 31 | AC31: =SUM(W31:AB31) -> 0 | AD31: 52 | AE31: 12 | AJ31: =SUM(AD31:AI31) -> 64 | AK31: 145 | AL31: 50 | AN31: 1 | AO31: 4 | AQ31: =SUM(AK31:AP31) -> 200 | AR31: 19 | AS31: 9 | AX31: =SUM(AR31:AW31) -> 28 | AY31: 52 | AZ31: 13 | BD31: 1 | BE31: =SUM(AY31:BD31) -> 66 | BF31: 2 | BL31: =SUM(BF31:BK31) -> 2 | BM31: 61 | BN31: 14 | BS31: =SUM(BM31:BR31) -> 75 | BT31: 63 | BU31: 12 | BZ31: =SUM(BT31:BY31) -> 75 | CG31: =SUM(CA31:CF31) -> 0 | CH31: 18 | CI31: 8 | CL31: 1 | CN31: =SUM(CH31:CM31) -> 27 | CO31: 103 | CP31: 22 | CU31: =SUM(CO31:CT31) -> 125 | DB31: =SUM(CV31:DA31) -> 0 | DI31: =SUM(DC31:DH31) -> 0 | DP31: =SUM(DJ31:DO31) -> 0 | DW31: =SUM(DQ31:DV31) -> 0 | ED31: =SUM(DX31:EC31) -> 0 | ER31: =SUM(EL31:EQ31) -> 0 | EY31: =SUM(ES31:EX31) -> 0 | FF31: =SUM(EZ31:FE31) -> 0 | FT31: =SUM(FN31:FS31) -> 0 | GA31: =SUM(FU31:FZ31) -> 0 | GH31: =SUM(GB31:GG31) -> 0 | GV31: =SUM(GP31:GU31) -> 0 | HC31: =SUM(GW31:HB31) -> 0 | HJ31: =SUM(HD31:HI31) -> 0
A32: 14.15-14.30 | B32: 41 | C32: 6 | H32: =SUM(B32:G32) -> 47 | I32: 42 | J32: 9 | M32: 1 | O32: =SUM(I32:N32) -> 52 | P32: 17 | Q32: 6 | V32: =SUM(P32:U32) -> 23 | AC32: =SUM(W32:AB32) -> 0 | AD32: 39 | AE32: 17 | AJ32: =SUM(AD32:AI32) -> 56 | AK32: 163 | AL32: 48 | AO32: 7 | AQ32: =SUM(AK32:AP32) -> 218 | AR32: 22 | AS32: 10 | AX32: =SUM(AR32:AW32) -> 32 | AY32: 39 | AZ32: 10 | BC32: 1 | BE32: =SUM(AY32:BD32) -> 50 | BF32: 4 | BG32: 2 | BL32: =SUM(BF32:BK32) -> 6 | BM32: 54 | BN32: 16 | BQ32: 2 | BS32: =SUM(BM32:BR32) -> 72 | BT32: 79 | BU32: 6 | BZ32: =SUM(BT32:BY32) -> 85 | CG32: =SUM(CA32:CF32) -> 0 | CH32: 22 | CI32: 5 | CN32: =SUM(CH32:CM32) -> 27 | CO32: 110 | CP32: 20 | CS32: 1 | CT32: 1 | CU32: =SUM(CO32:CT32) -> 132 | DB32: =SUM(CV32:DA32) -> 0 | DI32: =SUM(DC32:DH32) -> 0 | DP32: =SUM(DJ32:DO32) -> 0 | DW32: =SUM(DQ32:DV32) -> 0 | ED32: =SUM(DX32:EC32) -> 0 | ER32: =SUM(EL32:EQ32) -> 0 | EY32: =SUM(ES32:EX32) -> 0 | FF32: =SUM(EZ32:FE32) -> 0 | FT32: =SUM(FN32:FS32) -> 0 | GA32: =SUM(FU32:FZ32) -> 0 | GH32: =SUM(GB32:GG32) -> 0 | GV32: =SUM(GP32:GU32) -> 0 | HC32: =SUM(GW32:HB32) -> 0 | HJ32: =SUM(HD32:HI32) -> 0
A33: 14.30-14.45 | B33: 35 | C33: 12 | H33: =SUM(B33:G33) -> 47 | I33: 44 | J33: 10 | O33: =SUM(I33:N33) -> 54 | P33: 23 | Q33: 6 | T33: 1 | V33: =SUM(P33:U33) -> 30 | AC33: =SUM(W33:AB33) -> 0 | AD33: 44 | AE33: 14 | AJ33: =SUM(AD33:AI33) -> 58 | AK33: 158 | AL33: 42 | AM33: 1 | AO33: 6 | AP33: 1 | AQ33: =SUM(AK33:AP33) -> 208 | AR33: 21 | AS33: 6 | AX33: =SUM(AR33:AW33) -> 27 | AY33: 42 | AZ33: 12 | BA33: 1 | BC33: 3 | BE33: =SUM(AY33:BD33) -> 58 | BF33: 3 | BG33: 1 | BJ33: 2 | BL33: =SUM(BF33:BK33) -> 6 | BM33: 63 | BN33: 14 | BS33: =SUM(BM33:BR33) -> 77 | BT33: 72 | BU33: 14 | BZ33: =SUM(BT33:BY33) -> 86 | CG33: =SUM(CA33:CF33) -> 0 | CH33: 25 | CI33: 6 | CN33: =SUM(CH33:CM33) -> 31 | CO33: 106 | CP33: 24 | CQ33: 1 | CU33: =SUM(CO33:CT33) -> 131 | DB33: =SUM(CV33:DA33) -> 0 | DI33: =SUM(DC33:DH33) -> 0 | DP33: =SUM(DJ33:DO33) -> 0 | DW33: =SUM(DQ33:DV33) -> 0 | ED33: =SUM(DX33:EC33) -> 0 | ER33: =SUM(EL33:EQ33) -> 0 | EY33: =SUM(ES33:EX33) -> 0 | FF33: =SUM(EZ33:FE33) -> 0 | FT33: =SUM(FN33:FS33) -> 0 | GA33: =SUM(FU33:FZ33) -> 0 | GH33: =SUM(GB33:GG33) -> 0 | GV33: =SUM(GP33:GU33) -> 0 | HC33: =SUM(GW33:HB33) -> 0 | HJ33: =SUM(HD33:HI33) -> 0
A34: 14.45-15.00 | B34: 46 | C34: 8 | F34: 1 | G34: 1 | H34: =SUM(B34:G34) -> 56 | I34: 48 | J34: 10 | O34: =SUM(I34:N34) -> 58 | P34: 15 | Q34: 13 | V34: =SUM(P34:U34) -> 28 | AC34: =SUM(W34:AB34) -> 0 | AD34: 48 | AE34: 20 | AH34: 1 | AJ34: =SUM(AD34:AI34) -> 69 | AK34: 171 | AL34: 49 | AN34: 1 | AO34: 6 | AQ34: =SUM(AK34:AP34) -> 227 | AR34: 18 | AS34: 4 | AV34: 1 | AX34: =SUM(AR34:AW34) -> 23 | AY34: 35 | AZ34: 15 | BE34: =SUM(AY34:BD34) -> 50 | BF34: 6 | BL34: =SUM(BF34:BK34) -> 6 | BM34: 54 | BN34: 12 | BS34: =SUM(BM34:BR34) -> 66 | BT34: 54 | BU34: 11 | BZ34: =SUM(BT34:BY34) -> 65 | CG34: =SUM(CA34:CF34) -> 0 | CH34: 34 | CI34: 9 | CL34: 1 | CN34: =SUM(CH34:CM34) -> 44 | CO34: 96 | CP34: 19 | CQ34: 1 | CR34: 2 | CS34: 1 | CU34: =SUM(CO34:CT34) -> 119 | DB34: =SUM(CV34:DA34) -> 0 | DI34: =SUM(DC34:DH34) -> 0 | DP34: =SUM(DJ34:DO34) -> 0 | DW34: =SUM(DQ34:DV34) -> 0 | ED34: =SUM(DX34:EC34) -> 0 | ER34: =SUM(EL34:EQ34) -> 0 | EY34: =SUM(ES34:EX34) -> 0 | FF34: =SUM(EZ34:FE34) -> 0 | FT34: =SUM(FN34:FS34) -> 0 | GA34: =SUM(FU34:FZ34) -> 0 | GH34: =SUM(GB34:GG34) -> 0 | GV34: =SUM(GP34:GU34) -> 0 | HC34: =SUM(GW34:HB34) -> 0 | HJ34: =SUM(HD34:HI34) -> 0
A35: 15.00-15.15 | B35: 39 | C35: 10 | H35: =SUM(B35:G35) -> 49 | I35: 39 | J35: 8 | O35: =SUM(I35:N35) -> 47 | P35: 18 | Q35: 7 | T35: 1 | V35: =SUM(P35:U35) -> 26 | AC35: =SUM(W35:AB35) -> 0 | AD35: 42 | AE35: 16 | AJ35: =SUM(AD35:AI35) -> 58 | AK35: 152 | AL35: 48 | AO35: 4 | AQ35: =SUM(AK35:AP35) -> 204 | AR35: 24 | AS35: 8 | AX35: =SUM(AR35:AW35) -> 32 | AY35: 49 | AZ35: 24 | BE35: =SUM(AY35:BD35) -> 73 | BF35: 2 | BG35: 3 | BJ35: 1 | BL35: =SUM(BF35:BK35) -> 6 | BM35: 61 | BN35: 14 | BQ35: 1 | BS35: =SUM(BM35:BR35) -> 76 | BT35: 62 | BU35: 4 | BZ35: =SUM(BT35:BY35) -> 66 | CG35: =SUM(CA35:CF35) -> 0 | CH35: 29 | CI35: 7 | CN35: =SUM(CH35:CM35) -> 36 | CO35: 93 | CP35: 22 | CU35: =SUM(CO35:CT35) -> 115 | DB35: =SUM(CV35:DA35) -> 0 | DI35: =SUM(DC35:DH35) -> 0 | DP35: =SUM(DJ35:DO35) -> 0 | DW35: =SUM(DQ35:DV35) -> 0 | ED35: =SUM(DX35:EC35) -> 0 | ER35: =SUM(EL35:EQ35) -> 0 | EY35: =SUM(ES35:EX35) -> 0 | FF35: =SUM(EZ35:FE35) -> 0 | FT35: =SUM(FN35:FS35) -> 0 | GA35: =SUM(FU35:FZ35) -> 0 | GH35: =SUM(GB35:GG35) -> 0 | GV35: =SUM(GP35:GU35) -> 0 | HC35: =SUM(GW35:HB35) -> 0 | HJ35: =SUM(HD35:HI35) -> 0
A36: 15.15-15.30 | B36: 34 | C36: 10 | H36: =SUM(B36:G36) -> 44 | I36: 42 | J36: 11 | O36: =SUM(I36:N36) -> 53 | P36: 27 | Q36: 10 | V36: =SUM(P36:U36) -> 37 | AC36: =SUM(W36:AB36) -> 0 | AD36: 53 | AE36: 13 | AJ36: =SUM(AD36:AI36) -> 66 | AK36: 141 | AL36: 53 | AM36: 1 | AO36: 3 | AQ36: =SUM(AK36:AP36) -> 198 | AR36: 21 | AS36: 9 | AX36: =SUM(AR36:AW36) -> 30 | AY36: 39 | AZ36: 19 | BA36: 1 | BE36: =SUM(AY36:BD36) -> 59 | BF36: 8 | BG36: 1 | BL36: =SUM(BF36:BK36) -> 9 | BM36: 52 | BN36: 12 | BS36: =SUM(BM36:BR36) -> 64 | BT36: 42 | BU36: 7 | BZ36: =SUM(BT36:BY36) -> 49 | CG36: =SUM(CA36:CF36) -> 0 | CH36: 38 | CI36: 11 | CN36: =SUM(CH36:CM36) -> 49 | CO36: 119 | CP36: 24 | CQ36: 1 | CU36: =SUM(CO36:CT36) -> 144 | DB36: =SUM(CV36:DA36) -> 0 | DI36: =SUM(DC36:DH36) -> 0 | DP36: =SUM(DJ36:DO36) -> 0 | DW36: =SUM(DQ36:DV36) -> 0 | ED36: =SUM(DX36:EC36) -> 0 | ER36: =SUM(EL36:EQ36) -> 0 | EY36: =SUM(ES36:EX36) -> 0 | FF36: =SUM(EZ36:FE36) -> 0 | FT36: =SUM(FN36:FS36) -> 0 | GA36: =SUM(FU36:FZ36) -> 0 | GH36: =SUM(GB36:GG36) -> 0 | GV36: =SUM(GP36:GU36) -> 0 | HC36: =SUM(GW36:HB36) -> 0 | HJ36: =SUM(HD36:HI36) -> 0
A37: 15.30-15.45 | B37: 42 | C37: 7 | D37: 1 | F37: 1 | G37: 3 | H37: =SUM(B37:G37) -> 54 | I37: 40 | J37: 12 | O37: =SUM(I37:N37) -> 52 | P37: 25 | Q37: 5 | V37: =SUM(P37:U37) -> 30 | AC37: =SUM(W37:AB37) -> 0 | AD37: 57 | AE37: 19 | AJ37: =SUM(AD37:AI37) -> 76 | AK37: 168 | AL37: 44 | AN37: 1 | AO37: 5 | AP37: 1 | AQ37: =SUM(AK37:AP37) -> 219 | AR37: 29 | AS37: 6 | AX37: =SUM(AR37:AW37) -> 35 | AY37: 58 | AZ37: 26 | BC37: 2 | BD37: 1 | BE37: =SUM(AY37:BD37) -> 87 | BF37: 3 | BL37: =SUM(BF37:BK37) -> 3 | BM37: 57 | BN37: 16 | BS37: =SUM(BM37:BR37) -> 73 | BT37: 37 | BU37: 19 | BZ37: =SUM(BT37:BY37) -> 56 | CG37: =SUM(CA37:CF37) -> 0 | CH37: 42 | CI37: 12 | CL37: 1 | CN37: =SUM(CH37:CM37) -> 55 | CO37: 103 | CP37: 28 | CS37: 2 | CT37: 1 | CU37: =SUM(CO37:CT37) -> 134 | DB37: =SUM(CV37:DA37) -> 0 | DI37: =SUM(DC37:DH37) -> 0 | DP37: =SUM(DJ37:DO37) -> 0 | DW37: =SUM(DQ37:DV37) -> 0 | ED37: =SUM(DX37:EC37) -> 0 | ER37: =SUM(EL37:EQ37) -> 0 | EY37: =SUM(ES37:EX37) -> 0 | FF37: =SUM(EZ37:FE37) -> 0 | FT37: =SUM(FN37:FS37) -> 0 | GA37: =SUM(FU37:FZ37) -> 0 | GH37: =SUM(GB37:GG37) -> 0 | GV37: =SUM(GP37:GU37) -> 0 | HC37: =SUM(GW37:HB37) -> 0 | HJ37: =SUM(HD37:HI37) -> 0
A38: 15.45-16.00 | B38: 35 | C38: 11 | H38: =SUM(B38:G38) -> 46 | I38: 37 | J38: 9 | O38: =SUM(I38:N38) -> 46 | P38: 20 | Q38: 9 | V38: =SUM(P38:U38) -> 29 | AC38: =SUM(W38:AB38) -> 0 | AD38: 49 | AE38: 21 | AH38: 1 | AJ38: =SUM(AD38:AI38) -> 71 | AK38: 137 | AL38: 57 | AM38: 1 | AO38: 4 | AQ38: =SUM(AK38:AP38) -> 199 | AR38: 33 | AS38: 8 | AX38: =SUM(AR38:AW38) -> 41 | AY38: 62 | AZ38: 13 | BC38: 1 | BE38: =SUM(AY38:BD38) -> 76 | BF38: 5 | BL38: =SUM(BF38:BK38) -> 5 | BM38: 64 | BN38: 15 | BQ38: 1 | BS38: =SUM(BM38:BR38) -> 80 | BT38: 51 | BU38: 12 | BZ38: =SUM(BT38:BY38) -> 63 | CG38: =SUM(CA38:CF38) -> 0 | CH38: 40 | CI38: 10 | CN38: =SUM(CH38:CM38) -> 50 | CO38: 117 | CP38: 20 | CS38: 2 | CU38: =SUM(CO38:CT38) -> 139 | DB38: =SUM(CV38:DA38) -> 0 | DI38: =SUM(DC38:DH38) -> 0 | DP38: =SUM(DJ38:DO38) -> 0 | DW38: =SUM(DQ38:DV38) -> 0 | ED38: =SUM(DX38:EC38) -> 0 | ER38: =SUM(EL38:EQ38) -> 0 | EY38: =SUM(ES38:EX38) -> 0 | FF38: =SUM(EZ38:FE38) -> 0 | FT38: =SUM(FN38:FS38) -> 0 | GA38: =SUM(FU38:FZ38) -> 0 | GH38: =SUM(GB38:GG38) -> 0 | GV38: =SUM(GP38:GU38) -> 0 | HC38: =SUM(GW38:HB38) -> 0 | HJ38: =SUM(HD38:HI38) -> 0
A39: 16.00-16.15 | B39: 38 | C39: 9 | F39: 2 | G39: 1 | H39: =SUM(B39:G39) -> 50 | I39: 28 | J39: 13 | O39: =SUM(I39:N39) -> 41 | P39: 26 | Q39: 12 | T39: 1 | V39: =SUM(P39:U39) -> 39 | AC39: =SUM(W39:AB39) -> 0 | AD39: 61 | AE39: 17 | AJ39: =SUM(AD39:AI39) -> 78 | AK39: 159 | AL39: 46 | AO39: 2 | AQ39: =SUM(AK39:AP39) -> 207 | AR39: 39 | AS39: 10 | AV39: 1 | AW39: 1 | AX39: =SUM(AR39:AW39) -> 51 | AY39: 50 | AZ39: 25 | BD39: 1 | BE39: =SUM(AY39:BD39) -> 76 | BF39: 7 | BG39: 2 | BJ39: 2 | BL39: =SUM(BF39:BK39) -> 11 | BM39: 59 | BN39: 17 | BS39: =SUM(BM39:BR39) -> 76 | BT39: 42 | BU39: 21 | BZ39: =SUM(BT39:BY39) -> 63 | CG39: =SUM(CA39:CF39) -> 0 | CH39: 46 | CI39: 7 | CL39: 1 | CN39: =SUM(CH39:CM39) -> 54 | CO39: 129 | CP39: 40 | CR39: 2 | CS39: 4 | CU39: =SUM(CO39:CT39) -> 175 | DB39: =SUM(CV39:DA39) -> 0 | DI39: =SUM(DC39:DH39) -> 0 | DP39: =SUM(DJ39:DO39) -> 0 | DW39: =SUM(DQ39:DV39) -> 0 | ED39: =SUM(DX39:EC39) -> 0 | ER39: =SUM(EL39:EQ39) -> 0 | EY39: =SUM(ES39:EX39) -> 0 | FF39: =SUM(EZ39:FE39) -> 0 | FT39: =SUM(FN39:FS39) -> 0 | GA39: =SUM(FU39:FZ39) -> 0 | GH39: =SUM(GB39:GG39) -> 0 | GV39: =SUM(GP39:GU39) -> 0 | HC39: =SUM(GW39:HB39) -> 0 | HJ39: =SUM(HD39:HI39) -> 0
A40: 16.15-16.30 | B40: 46 | C40: 9 | H40: =SUM(B40:G40) -> 55 | I40: 32 | J40: 10 | O40: =SUM(I40:N40) -> 42 | P40: 24 | Q40: 14 | T40: 2 | V40: =SUM(P40:U40) -> 40 | AC40: =SUM(W40:AB40) -> 0 | AD40: 54 | AE40: 14 | AF40: 1 | AI40: 1 | AJ40: =SUM(AD40:AI40) -> 70 | AK40: 172 | AL40: 51 | AM40: 1 | AO40: 1 | AQ40: =SUM(AK40:AP40) -> 225 | AR40: 37 | AS40: 8 | AV40: 1 | AX40: =SUM(AR40:AW40) -> 46 | AY40: 41 | AZ40: 18 | BA40: 2 | BC40: 1 | BE40: =SUM(AY40:BD40) -> 62 | BF40: 4 | BG40: 1 | BJ40: 2 | BL40: =SUM(BF40:BK40) -> 7 | BM40: 62 | BN40: 14 | BS40: =SUM(BM40:BR40) -> 76 | BT40: 47 | BU40: 13 | BZ40: =SUM(BT40:BY40) -> 60 | CG40: =SUM(CA40:CF40) -> 0 | CH40: 53 | CI40: 8 | CN40: =SUM(CH40:CM40) -> 61 | CO40: 133 | CP40: 43 | CS40: 2 | CU40: =SUM(CO40:CT40) -> 178 | DB40: =SUM(CV40:DA40) -> 0 | DI40: =SUM(DC40:DH40) -> 0 | DP40: =SUM(DJ40:DO40) -> 0 | DW40: =SUM(DQ40:DV40) -> 0 | ED40: =SUM(DX40:EC40) -> 0 | ER40: =SUM(EL40:EQ40) -> 0 | EY40: =SUM(ES40:EX40) -> 0 | FF40: =SUM(EZ40:FE40) -> 0 | FT40: =SUM(FN40:FS40) -> 0 | GA40: =SUM(FU40:FZ40) -> 0 | GH40: =SUM(GB40:GG40) -> 0 | GV40: =SUM(GP40:GU40) -> 0 | HC40: =SUM(GW40:HB40) -> 0 | HJ40: =SUM(HD40:HI40) -> 0
...

Sheet Queue
A1: NB | B1: 01 | C1: 02 | D1: 03 | E1: 04 | F1: 05 | G1: 06 | H1: 07 | I1: 08 | J1: 09 | K1: 10 | L1: 11 | M1: 12 | N1: 13 | O1: 14 | P1: 15 | Q1: 16 | R1: 17 | S1: 18 | T1: 19 | U1: 20 | V1: 21 | W1: 22 | X1: 23 | Y1: 24 | Z1: 25 | AA1: 26 | AB1: 27 | AC1: 28 | AD1: 29 | AE1: 30 | AF1: 31 | AG1: 32 | AH1: 33 | AI1: 34 | AJ1: 35
A2: 7.00-8.00 | B2: 50 | C2: 50 | D2: 50 | E2: 50 | F2: 50 | G2: 50 | H2: 50 | I2: 80 | J2: 80 | K2: 80 | L2: 80 | M2: 100 | N2: 100 | O2: 100 | P2: 100 | Q2: 100 | AK2: =COUNTA(B2:AJ2) -> 16 | AL2: =SUM(B2:AJ2)/AK2 -> 73.125
A3: 8.01-9.00 | B3: 100 | C3: 80 | D3: 80 | AK3: =COUNTA(B3:AJ3) -> 3 | AL3: =SUM(B3:AJ3)/AK3 -> 86.666667
A4: 9.01-10.00 | B4: 80 | C4: 50 | D4: 50 | E4: 50 | F4: 50 | AK4: =COUNTA(B4:AJ4) -> 5 | AL4: =SUM(B4:AJ4)/AK4 -> 56
A5: 10.01-11.00 | B5: 50 | AK5: =COUNTA(B5:AJ5) -> 1 | AL5: =SUM(B5:AJ5)/AK5 -> 50
A6: 11.01-12.00 | B6: 80 | AK6: =COUNTA(B6:AJ6) -> 1 | AL6: =SUM(B6:AJ6)/AK6 -> 80
A7: 12.01-13.00 | B7: 80 | C7: 80 | D7: 80 | E7: 100 | F7: 100 | G7: 100 | H7: 100 | I7: 80 | J7: 80 | K7: 80 | L7: 80 | M7: 80 | N7: 80 | O7: 80 | P7: 80 | AK7: =COUNTA(B7:AJ7) -> 15 | AL7: =SUM(B7:AJ7)/AK7 -> 85.333333
A8: 13.01-14.00 | B8: 80 | AK8: =COUNTA(B8:AJ8) -> 1 | AL8: =SUM(B8:AJ8)/AK8 -> 80
A9: 14.01-15.00 | B9: 80 | C9: 80 | D9: 80 | E9: 80 | F9: 90 | G9: 90 | H9: 90 | I9: 90 | J9: 90 | K9: 90 | L9: 90 | M9: 100 | N9: 100 | AK9: =COUNTA(B9:AJ9) -> 13 | AL9: =SUM(B9:AJ9)/AK9 -> 88.461538
A10: 15.01-16.00 | B10: 100 | C10: 100 | D10: 100 | E10: 100 | F10: 100 | G10: 100 | H10: 100 | I10: 80 | AK10: =COUNTA(B10:AJ10) -> 8 | AL10: =SUM(B10:AJ10)/AK10 -> 97.5
A11: 16.01-17.00 | B11: 80 | C11: 110 | D11: 110 | E11: 100 | F11: 100 | G11: 100 | H11: 100 | AK11: =COUNTA(B11:AJ11) -> 7 | AL11: =SUM(B11:AJ11)/AK11 -> 100
A12: 17.01-18.00 | B12: 100 | C12: 80 | D12: 80 | E12: 80 | F12: 80 | G12: 80 | H12: 80 | I12: 80 | J12: 80 | K12: 80 | L12: 80 | M12: 80 | AK12: =COUNTA(B12:AJ12) -> 12 | AL12: =SUM(B12:AJ12)/AK12 -> 81.666667
A13: 18.01-19.00 | B13: 80 | C13: 70 | D13: 70 | E13: 70 | F13: 70 | G13: 70 | H13: 70 | I13: 70 | J13: 70 | K13: 70 | AK13: =COUNTA(B13:AJ13) -> 10 | AL13: =SUM(B13:AJ13)/AK13 -> 71
B14: 0
A15: EB | B15: 0
A16: 7.00-8.00 | B16: 80 | C16: 80 | D16: 80 | E16: 80 | F16: 80 | G16: 100 | H16: 100 | I16: 100 | J16: 100 | K16: 120 | L16: 120 | M16: 120 | N16: 150 | O16: 150 | P16: 180 | Q16: 180 | AK16: =COUNTA(B16:AJ16) -> 16 | AL16: =SUM(B16:AJ16)/AK16 -> 113.75
A17: 8.01-9.00 | B17: 200 | AK17: =COUNTA(B17:AJ17) -> 1 | AL17: =SUM(B17:AJ17)/AK17 -> 200
A18: 9.01-10.00 | B18: 180 | C18: 150 | D18: 150 | E18: 120 | F18: 120 | AK18: =COUNTA(B18:AJ18) -> 5 | AL18: =SUM(B18:AJ18)/AK18 -> 144
A19: 10.01-11.00 | B19: 120 | C19: 100 | D19: 100 | E19: 100 | AK19: =COUNTA(B19:AJ19) -> 4 | AL19: =SUM(B19:AJ19)/AK19 -> 105
A20: 11.01-12.00 | B20: 100 | C20: 100 | D20: 120 | E20: 120 | AK20: =COUNTA(B20:AJ20) -> 4 | AL20: =SUM(B20:AJ20)/AK20 -> 110
A21: 12.01-13.00 | B21: 120 | C21: 150 | D21: 150 | E21: 150 | F21: 150 | G21: 150 | H21: 120 | I21: 120 | J21: 120 | K21: 120 | L21: 120 | M21: 120 | N21: 120 | O21: 120 | P21: 120 | AK21: =COUNTA(B21:AJ21) -> 15 | AL21: =SUM(B21:AJ21)/AK21 -> 130
A22: 13.01-14.00 | B22: 120 | AK22: =COUNTA(B22:AJ22) -> 1 | AL22: =SUM(B22:AJ22)/AK22 -> 120
A23: 14.01-15.00 | B23: 120 | C23: 120 | D23: 120 | E23: 120 | F23: 120 | G23: 120 | H23: 120 | I23: 120 | J23: 120 | K23: 120 | L23: 120 | M23: 120 | N23: 150 | AK23: =COUNTA(B23:AJ23) -> 13 | AL23: =SUM(B23:AJ23)/AK23 -> 122.30769
A24: 15.01-16.00 | B24: 150 | C24: 150 | D24: 150 | E24: 150 | F24: 150 | G24: 100 | H24: 100 | I24: 120 | AK24: =COUNTA(B24:AJ24) -> 8 | AL24: =SUM(B24:AJ24)/AK24 -> 133.75
A25: 16.01-17.00 | B25: 120 | C25: 150 | D25: 150 | E25: 150 | F25: 150 | G25: 150 | H25: 150 | AK25: =COUNTA(B25:AJ25) -> 7 | AL25: =SUM(B25:AJ25)/AK25 -> 145.71429
A26: 17.01-18.00 | B26: 150 | AK26: =COUNTA(B26:AJ26) -> 1 | AL26: =SUM(B26:AJ26)/AK26 -> 150
A27: 18.01-19.00 | B27: 150 | AK27: =COUNTA(B27:AJ27) -> 1 | AL27: =SUM(B27:AJ27)/AK27 -> 150
B28: 0
A29: SB | B29: 0
A30: 7.00-8.00 | B30: 80 | C30: 80 | D30: 80 | E30: 80 | F30: 100 | G30: 100 | H30: 100 | I30: 100 | J30: 120 | K30: 120 | L30: 120 | M30: 120 | N30: 150 | O30: 150 | P30: 180 | AK30: =COUNTA(B30:AJ30) -> 15 | AL30: =SUM(B30:AJ30)/AK30 -> 112
A31: 8.01-9.00 | B31: 180 | C31: 200 | D31: 200 | E31: 200 | AK31: =COUNTA(B31:AJ31) -> 4 | AL31: =SUM(B31:AJ31)/AK31 -> 195
A32: 9.01-10.00 | B32: 180 | C32: 150 | D32: 120 | E32: 100 | F32: 80 | AK32: =COUNTA(B32:AJ32) -> 5 | AL32: =SUM(B32:AJ32)/AK32 -> 126
A33: 10.01-11.00 | B33: 80 | AK33: =COUNTA(B33:AJ33) -> 1 | AL33: =SUM(B33:AJ33)/AK33 -> 80
A34: 11.01-12.00 | B34: 80 | AK34: =COUNTA(B34:AJ34) -> 1 | AL34: =SUM(B34:AJ34)/AK34 -> 80
A35: 12.01-13.00 | B35: 80 | AK35: =COUNTA(B35:AJ35) -> 1 | AL35: =SUM(B35:AJ35)/AK35 -> 80
A36: 13.01-14.00 | B36: 80 | AK36: =COUNTA(B36:AJ36) -> 1 | AL36: =SUM(B36:AJ36)/AK36 -> 80
A37: 14.01-15.00 | B37: 80 | C37: 80 | D37: 90 | E37: 100 | F37: 100 | G37: 100 | H37: 100 | I37: 100 | J37: 100 | K37: 100 | L37: 100 | M37: 100 | N37: 100 | O37: 100 | AK37: =COUNTA(B37:AJ37) -> 14 | AL37: =SUM(B37:AJ37)/AK37 -> 96.428571
A38: 15.01-16.00 | B38: 100 | C38: 100 | D38: 100 | E38: 100 | F38: 100 | G38: 100 | H38: 100 | I38: 120 | AK38: =COUNTA(B38:AJ38) -> 8 | AL38: =SUM(B38:AJ38)/AK38 -> 102.5
A39: 16.01-17.00 | B39: 120 | AK39: =COUNTA(B39:AJ39) -> 1 | AL39: =SUM(B39:AJ39)/AK39 -> 120
A40: 17.01-18.00 | B40: 120 | AK40: =COUNTA(B40:AJ40) -> 1 | AL40: =SUM(B40:AJ40)/AK40 -> 120
...

Sheet Report
A1: ชื่อทางแยก | B1: =Header!B3 -> หลักสี่ | I1: ข้อมูลปริมาณการจราจรบริเวณทางแยกในกรุงเทพมหานคร
A2: ถนน | B2: =Header!B6 -> แจ้งวัฒนะ - กำแพงเพชร | G2: หมายเลข | H2: =Header!B4 -> 500 | M2: วันที่ | N2: =Header!B7 -> 20 พฤษภาคม 2569 | S2: สภาพอากาศ | U2: =Header!B8 -> ปกติ
C3: SB | D3: =Header!B13 -> ถนนกำแพงเพชร 6 | G3: เวลา | J3: ปริมาณการจราจรแต่ละช่วงเวลา (คัน/ชม.) | P3: (ไม่รวมรถจักรยานยนต์) | U3: ปริมาณรถ | W3: เฉลี่ย
F4: ทิศทาง | H4: 07-08 | I4: 08-09 | J4: 09-10 | K4: 10-11 | L4: 11-12 | M4: 12-13 | N4: 13-14 | O4: 14-15 | P4: 15-16 | Q4: 16-17 | R4: 17-18 | S4: 18-19 | T4: รวม | U4: ค่าต่ำสุด | V4: ค่าสูงสุด | W4: PCU/HOUR
F5: NB | G5: 1 | H5: =VALUE(Analysis!$H$53) -> 208 | I5: =VALUE(Analysis!$H$54) -> 211 | J5: =VALUE(Analysis!$H$55) -> 182 | K5: =VALUE(Analysis!$H$56) -> 155 | L5: =VALUE(Analysis!$H$57) -> 154 | M5: =VALUE(Analysis!$H$58) -> 137 | N5: =VALUE(Analysis!$H$59) -> 131 | O5: =VALUE(Analysis!$H$60) -> 197 | P5: =VALUE(Analysis!$H$61) -> 193 | Q5: =VALUE(Analysis!$H$62) -> 227 | R5: =VALUE(Analysis!$H$63) -> 232 | S5: =VALUE(Analysis!$H$64) -> 184 | T5: =SUM($H5:$S5) -> 2211 | U5: =_xlfn.MINIFS($H5:$S5,$H5:$S5,">0") -> 131 | V5: =_xlfn.MAXIFS($H5:$S5,$H5:$S5,">0") -> 232 | W5: =VALUE(Analysis!$H$95) -> 187.6525
G6: 2 | H6: =VALUE(Analysis!$O$53) -> 117 | I6: =VALUE(Analysis!$O$54) -> 111 | J6: =VALUE(Analysis!$O$55) -> 250 | K6: =VALUE(Analysis!$O$56) -> 222 | L6: =VALUE(Analysis!$O$57) -> 245 | M6: =VALUE(Analysis!$O$58) -> 280 | N6: =VALUE(Analysis!$O$59) -> 238 | O6: =VALUE(Analysis!$O$60) -> 210 | P6: =VALUE(Analysis!$O$61) -> 198 | Q6: =VALUE(Analysis!$O$62) -> 174 | R6: =VALUE(Analysis!$O$63) -> 140 | S6: =VALUE(Analysis!$O$64) -> 134 | T6: =SUM($H6:$S6) -> 2319 | U6: =_xlfn.MINIFS($H6:$S6,$H6:$S6,">0") -> 111 | V6: =_xlfn.MAXIFS($H6:$S6,$H6:$S6,">0") -> 280 | W6: =VALUE(Analysis!$O$95) -> 193.48833
G7: 3 | H7: =VALUE(Analysis!$V$53) -> 127 | I7: =VALUE(Analysis!$V$54) -> 102 | J7: =VALUE(Analysis!$V$55) -> 107 | K7: =VALUE(Analysis!$V$56) -> 142 | L7: =VALUE(Analysis!$V$57) -> 124 | M7: =VALUE(Analysis!$V$58) -> 106 | N7: =VALUE(Analysis!$V$59) -> 125 | O7: =VALUE(Analysis!$V$60) -> 112 | P7: =VALUE(Analysis!$V$61) -> 122 | Q7: =VALUE(Analysis!$V$62) -> 166 | R7: =VALUE(Analysis!$V$63) -> 121 | S7: =VALUE(Analysis!$V$64) -> 83 | T7: =SUM($H7:$S7) -> 1437 | U7: =_xlfn.MINIFS($H7:$S7,$H7:$S7,">0") -> 83 | V7: =_xlfn.MAXIFS($H7:$S7,$H7:$S7,">0") -> 166 | W7: =VALUE(Analysis!$V$95) -> 121
A8: =Header!B12 -> ถนนแจ้งวัฒนะ | G8: 4 | H8: =VALUE(Analysis!$AC$53) -> 0 | I8: =VALUE(Analysis!$AC$54) -> 0 | J8: =VALUE(Analysis!$AC$55) -> 0 | K8: =VALUE(Analysis!$AC$56) -> 0 | L8: =VALUE(Analysis!$AC$57) -> 0 | M8: =VALUE(Analysis!$AC$58) -> 0 | N8: =VALUE(Analysis!$AC$59) -> 0 | O8: =VALUE(Analysis!$AC$60) -> 0 | P8: =VALUE(Analysis!$AC$61) -> 0 | Q8: =VALUE(Analysis!$AC$62) -> 0 | R8: =VALUE(Analysis!$AC$63) -> 0 | S8: =VALUE(Analysis!$AC$64) -> 0 | T8: =SUM($H8:$S8) -> 0 | U8: =_xlfn.MINIFS($H8:$S8,$H8:$S8,">0") -> 0 | V8: =_xlfn.MAXIFS($H8:$S8,$H8:$S8,">0") -> 0 | W8: =VALUE(Analysis!$AC$95) -> 0
G9: 1* | H9: =VALUE(Analysis!$DP$53) -> 0 | I9: =VALUE(Analysis!$DP$54) -> 0 | J9: =VALUE(Analysis!$DP$55) -> 0 | K9: =VALUE(Analysis!$DP$56) -> 0 | L9: =VALUE(Analysis!$DP$57) -> 0 | M9: =VALUE(Analysis!$DP$58) -> 0 | N9: =VALUE(Analysis!$DP$59) -> 0 | O9: =VALUE(Analysis!$DP$60) -> 0 | P9: =VALUE(Analysis!$DP$61) -> 0 | Q9: =VALUE(Analysis!$DP$62) -> 0 | R9: =VALUE(Analysis!$DP$63) -> 0 | S9: =VALUE(Analysis!$DP$64) -> 0 | T9: =SUM($H9:$S9) -> 0 | U9: =_xlfn.MINIFS($H9:$S9,$H9:$S9,">0") -> 0 | V9: =_xlfn.MAXIFS($H9:$S9,$H9:$S9,">0") -> 0 | W9: =VALUE(Analysis!$DP$95) -> 0
G10: 2* | H10: =VALUE(Analysis!$DW$53) -> 0 | I10: =VALUE(Analysis!$DW$54) -> 0 | J10: =VALUE(Analysis!$DW$55) -> 0 | K10: =VALUE(Analysis!$DW$56) -> 0 | L10: =VALUE(Analysis!$DW$57) -> 0 | M10: =VALUE(Analysis!$DW$58) -> 0 | N10: =VALUE(Analysis!$DW$59) -> 0 | O10: =VALUE(Analysis!$DW$60) -> 0 | P10: =VALUE(Analysis!$DW$61) -> 0 | Q10: =VALUE(Analysis!$DW$62) -> 0 | R10: =VALUE(Analysis!$DW$63) -> 0 | S10: =VALUE(Analysis!$DW$64) -> 0 | T10: =SUM($H10:$S10) -> 0 | U10: =_xlfn.MINIFS($H10:$S10,$H10:$S10,">0") -> 0 | V10: =_xlfn.MAXIFS($H10:$S10,$H10:$S10,">0") -> 0 | W10: =VALUE(Analysis!$DW$95) -> 0
G11: 3* | H11: =VALUE(Analysis!$ED$53) -> 0 | I11: =VALUE(Analysis!$ED$54) -> 0 | J11: =VALUE(Analysis!$ED$55) -> 0 | K11: =VALUE(Analysis!$ED$56) -> 0 | L11: =VALUE(Analysis!$ED$57) -> 0 | M11: =VALUE(Analysis!$ED$58) -> 0 | N11: =VALUE(Analysis!$ED$59) -> 0 | O11: =VALUE(Analysis!$ED$60) -> 0 | P11: =VALUE(Analysis!$ED$61) -> 0 | Q11: =VALUE(Analysis!$ED$62) -> 0 | R11: =VALUE(Analysis!$ED$63) -> 0 | S11: =VALUE(Analysis!$ED$64) -> 0 | T11: =SUM($H11:$S11) -> 0 | U11: =_xlfn.MINIFS($H11:$S11,$H11:$S11,">0") -> 0 | V11: =_xlfn.MAXIFS($H11:$S11,$H11:$S11,">0") -> 0 | W11: =VALUE(Analysis!$ED$95) -> 0
F12: เข้า | H12: =Analysis!$F68 -> 452 | I12: =Analysis!$F69 -> 424 | J12: =Analysis!$F70 -> 539 | K12: =Analysis!$F71 -> 519 | L12: =Analysis!$F72 -> 523 | M12: =Analysis!$F73 -> 523 | N12: =Analysis!$F74 -> 494 | O12: =Analysis!$F75 -> 519 | P12: =Analysis!$F76 -> 513 | Q12: =Analysis!$F77 -> 567 | R12: =Analysis!$F78 -> 493 | S12: =Analysis!$F79 -> 401 | T12: =SUM($H12:$S12) -> 5967 | U12: =_xlfn.MINIFS($H12:$S12,$H12:$S12,">0") -> 401 | V12: =_xlfn.MAXIFS($H12:$S12,$H12:$S12,">0") -> 567
F13: ออก | H13: =Analysis!$G68 -> 709 | I13: =Analysis!$G69 -> 722 | J13: =Analysis!$G70 -> 702 | K13: =Analysis!$G71 -> 540 | L13: =Analysis!$G72 -> 530 | M13: =Analysis!$G73 -> 500 | N13: =Analysis!$G74 -> 482 | O13: =Analysis!$G75 -> 529 | P13: =Analysis!$G76 -> 621 | Q13: =Analysis!$G77 -> 741 | R13: =Analysis!$G78 -> 818 | S13: =Analysis!$G79 -> 714 | T13: =SUM($H13:$S13) -> 7608 | U13: =_xlfn.MINIFS($H13:$S13,$H13:$S13,">0") -> 482 | V13: =_xlfn.MAXIFS($H13:$S13,$H13:$S13,">0") -> 818
G14: นาที | H14: 7.- | I14: 8.- | J14: 9.- | K14: 10.- | L14: 11.- | M14: 12.- | N14: 13.- | O14: 14.- | P14: 15.- | Q14: 16.- | R14: 17.- | S14: 18.- | T14: รวม
G15: 15 | H15: =Analysis!$B$68 -> 111 | I15: =Analysis!$B$69 -> 111 | J15: =Analysis!$B$70 -> 130 | K15: =Analysis!$B$71 -> 126 | L15: =Analysis!$B$72 -> 124 | M15: =Analysis!$B$73 -> 136 | N15: =Analysis!$B$74 -> 133 | O15: =Analysis!$B$75 -> 124 | P15: =Analysis!$B$76 -> 122 | Q15: =Analysis!$B$77 -> 130 | R15: =Analysis!$B$78 -> 123 | S15: =Analysis!$B$79 -> 114 | T15: =SUM(H15:S15) -> 1484
G16: 30 | H16: =Analysis!$C$68 -> 224 | I16: =Analysis!$C$69 -> 219 | J16: =Analysis!$C$70 -> 270 | K16: =Analysis!$C$71 -> 259 | L16: =Analysis!$C$72 -> 267 | M16: =Analysis!$C$73 -> 261 | N16: =Analysis!$C$74 -> 261 | O16: =Analysis!$C$75 -> 246 | P16: =Analysis!$C$76 -> 256 | Q16: =Analysis!$C$77 -> 267 | R16: =Analysis!$C$78 -> 250 | S16: =Analysis!$C$79 -> 206 | T16: =SUM(H16:S16) -> 2986
